Workbook

Sheet README
A1: Impact of PHI Re-engineering on the AWB SOW
A3: Purpose | B3: Shows how each of the 23 re-engineering opportunities affects Achieve Without Borders' SOW S343096 — which items change, what AWB must build differently, the indicative extra effort and cost, where scope could shrink, and when PHI must decide.
A4: Sources | B4: PHI Process Re-engineering Opportunities (RE-01 to RE-23); AWB SOW S343096 (vendor-signed 24 Sep 2026); PHI clarification letter Appendix A/B.
A5: Impact types | B5: Adoption only = AWB configures what is already scoped; PHI changes how it works. Design change = same SOW item, different specification agreed at BRD. Extends SOW scope = more than the item covers. Depends on Appendix A/B = relies on a gap item already raised with AWB. PHI internal = no AWB effort.
A6: Effort figures | B6: INDICATIVE PHI estimates in man-days, for negotiation only — not AWB quotes. They count only the effort beyond what Appendix A already asks AWB to price, so they do not double count the clarification letter.
A7: Offsets | B7: Where re-engineering could reduce SOW effort (e.g., consolidating three approval workflows into one DOA engine, removing gateway work from item #76, avoiding data-migration flex). Use them to fund the extensions.
A8: Rates | B8: Blue cells on the Summary sheet: PHP 10,000 (SOW base rate) and PHP 12,000 (flex / change-request rate). Change them to test scenarios.
A9: Key timing point | B9: BRD sign-off (end of week 4) is deemed accepted after 5 working days. Every design decision here must be in the BRD — after sign-off it becomes a change request at the higher rate.
A10: Yellow cells | B10: PHI and AWB responses: AWB estimate, agreed treatment, status.

Sheet Summary
A1: Summary — what re-engineering means for the AWB SOW
A2: All figures are formulas. Blue cells are assumptions you can change.
A4: Assumptions
A5: SOW base rate (PHP per man-day) | B5: 10000
A6: Flex / change-request rate (PHP per man-day) | B6: 12000
A8: Opportunities by impact on the SOW
A9: Impact type | B9: Opportunities | C9: Extra effort low (md) | D9: Extra effort high (md)
A10: Adoption only — configure as scoped | B10: =COUNTIF('RE to SOW Impact'!$G$5:$G$27,A10) -> 2 | C10: =SUMIF('RE to SOW Impact'!$G$5:$G$27,A10,'RE to SOW Impact'!$J$5:$J$27) -> 0 | D10: =SUMIF('RE to SOW Impact'!$G$5:$G$27,A10,'RE to SOW Impact'!$K$5:$K$27) -> 2
A11: Design change within existing SOW item | B11: =COUNTIF('RE to SOW Impact'!$G$5:$G$27,A11) -> 6 | C11: =SUMIF('RE to SOW Impact'!$G$5:$G$27,A11,'RE to SOW Impact'!$J$5:$J$27) -> 9 | D11: =SUMIF('RE to SOW Impact'!$G$5:$G$27,A11,'RE to SOW Impact'!$K$5:$K$27) -> 18
A12: Extends SOW scope | B12: =COUNTIF('RE to SOW Impact'!$G$5:$G$27,A12) -> 4 | C12: =SUMIF('RE to SOW Impact'!$G$5:$G$27,A12,'RE to SOW Impact'!$J$5:$J$27) -> 12 | D12: =SUMIF('RE to SOW Impact'!$G$5:$G$27,A12,'RE to SOW Impact'!$K$5:$K$27) -> 24
A13: Depends on Appendix A/B gap item | B13: =COUNTIF('RE to SOW Impact'!$G$5:$G$27,A13) -> 8 | C13: =SUMIF('RE to SOW Impact'!$G$5:$G$27,A13,'RE to SOW Impact'!$J$5:$J$27) -> 14 | D13: =SUMIF('RE to SOW Impact'!$G$5:$G$27,A13,'RE to SOW Impact'!$K$5:$K$27) -> 28
A14: PHI internal — no AWB effort | B14: =COUNTIF('RE to SOW Impact'!$G$5:$G$27,A14) -> 3 | C14: =SUMIF('RE to SOW Impact'!$G$5:$G$27,A14,'RE to SOW Impact'!$J$5:$J$27) -> 0 | D14: =SUMIF('RE to SOW Impact'!$G$5:$G$27,A14,'RE to SOW Impact'!$K$5:$K$27) -> 1
A15: Total | B15: =SUM(B10:B14) -> 23 | C15: =SUM(C10:C14) -> 35 | D15: =SUM(D10:D14) -> 73
A17: Indicative cost of the extra effort
A18: Scenario | B18: Low | C18: High | D18: Note
A19: Extra effort (man-days) | B19: ='RE to SOW Impact'!J28 -> 35 | C19: ='RE to SOW Impact'!K28 -> 73 | D19: Beyond Appendix A requests
A20: Possible offsets (man-days) | B20: ='RE to SOW Impact'!L28 -> 8 | C20: ='RE to SOW Impact'!M28 -> 25.16 | D20: DOA consolidation, #76 gateway, avoided migration flex
A21: Net extra effort (man-days) | B21: =MAX(0,B19-C20) -> 9.84 | C21: =MAX(0,C19-B20) -> 65 | D21: Low = least extra minus most offset; High = most extra minus least offset
A22: Net cost if in base scope (PHP, ex-VAT) | B22: =B21*$B$5 -> 98400 | C22: =C21*$B$5 -> 650000 | D22: At SOW base rate
A23: Net cost if raised as change requests (PHP, ex-VAT) | B23: =B21*$B$6 -> 118080 | C23: =C21*$B$6 -> 780000 | D23: At flex / CR rate
A24: Saving from agreeing it before BRD sign-off (PHP) | B24: =B23-B22 -> 19680 | C24: =C23-C22 -> 130000 | D24: Difference between the two rates
A26: SOW items touched
A27: §3.3 items touched by at least one opportunity | B27: =COUNTIF('SOW Item Impact'!$F$5:$F$104,"<>Unchanged") -> 60
A28: Dev-days of those items (SOW) | B28: =SUMIF('SOW Item Impact'!$F$5:$F$104,"<>Unchanged",'SOW Item Impact'!$D$5:$D$104) -> 370.08
A29: Share of itemized SOW dev-days touched | B29: =B28/SUM('SOW Item Impact'!$D$5:$D$104) -> 0.64572864
A31: Estimates are indicative PHI figures for negotiation, not AWB quotes. Ask AWB to confirm each on the RE to SOW Impact sheet (yellow columns).

Sheet RE to SOW Impact
A1: Re-engineering → SOW impact
A2: One row per opportunity. Figures in blue are PHI's indicative estimates. Yellow columns are for the negotiation.
A4: ID | B4: Opportunity | C4: SOW sections affected | D4: SOW §3.3 items affected | E4: Items (count) | F4: Dev-days of affected items (SOW) | G4: Impact on SOW | H4: What AWB must build or configure differently | I4: Linked Appendix item | J4: Extra effort low (md) | K4: Extra effort high (md) | L4: Possible offset low (md) | M4: Possible offset high (md) | N4: SOW phase where built | O4: Decide by | P4: Suggested SOW / BRD wording | Q4: Flex category if not in base | R4: Risk if not addressed | S4: AWB estimate (md) | T4: Agreed treatment | U4: Status
A5: RE-01 | B5: Driver-based budget with commitment control | C5: §3.1 G Finance Core (corporate & department budget; TORC budget) | D5: — | E5: 0 | F5: =SUMPRODUCT(ISNUMBER(SEARCH("#"&'SOW Item Impact'!$A$5:$A$104&",",D5&","))*'SOW Item Impact'!$D$5:$D$104) -> 0 | G5: Extends SOW scope | H5: Build a driver-based budget with versioned quarterly reforecasts. Check and reserve budget at purchase request for all spend (not only TORC), and route over-budget requests to the DOA approver before a PO is issued. | I5: A8 | J5: 3 | K5: 6 | L5: 0 | M5: 0 | N5: Phase 3 – Build Wave 2 (wk 9–14) | O5: Now — before BRD sign-off (wk 4) | P5: Budget control applies at purchase-request (commitment) stage for all spend, with reserved amounts released on PO cancellation. | Q5: Change Order | R5: Budget stays a reporting tool; overspend is found only after bills post. | U5: Open
A6: RE-02 | B6: One digital Delegation of Authority matrix | C6: §3.4 Custom workflows (approval matrices); §3.1 B subcontractor approval matrix | D6: #21, #45, #60, #62, #63, #64 | E6: 6 | F6: =SUMPRODUCT(ISNUMBER(SEARCH("#"&'SOW Item Impact'!$A$5:$A$104&",",D6&","))*'SOW Item Impact'!$D$5:$D$104) -> 36 | G6: Design change within existing SOW item | H6: Build one configurable DOA engine (document type × amount × risk) used by every approval flow, with parallel steps, SLA escalation, auto-approval below threshold and a sampling flag — instead of separate Project, Lot and Broker approval workflows. | I6: — | J6: 2 | K6: 4 | L6: 5 | M6: 11.52 | N6: Phase 2 – Build Wave 1 (wk 5–10) | O6: Now — before BRD sign-off (wk 4) | P6: All approval workflows (#21, #45, #60, #62–64, subcontractor billing) use a single DOA matrix that PHI can maintain without code changes. | Q6: User Access and Approval Matrix | R6: Three or more hard-coded workflows; every DOA change becomes a change request. | U6: Open
A7: RE-03 | B7: Two-stage land due diligence with deal scorecard | C7: §3.1 C Land Acquisition | D7: #7, #20, #21, #86 | E7: 4 | F7: =SUMPRODUCT(ISNUMBER(SEARCH("#"&'SOW Item Impact'!$A$5:$A$104&",",D7&","))*'SOW Item Impact'!$D$5:$D$104) -> 24.48 | G7: Design change within existing SOW item | H7: Split the DD checklist into a knock-out stage and a full stage, allow parallel task assignment, and add a standard deal scorecard view for ManCom. | I7: — | J7: 2 | K7: 3 | L7: 0 | M7: 0 | N7: Phase 2 – Build Wave 1 (wk 5–10) | O7: Now — before BRD sign-off (wk 4) | P7: DD checklists support staged gates (knock-out, full) with parallel tasks and a standard scorecard report. | Q7: Requirements Analysis | R7: DD stays sequential in the system; doomed deals consume DD spend. | U7: Open
A8: RE-04 | B8: Evidence-based land payments and filing calendar | C8: §3.1 C Acquisition & Payments | D8: #24, #26, #29, #60 | E8: 4 | F8: =SUMPRODUCT(ISNUMBER(SEARCH("#"&'SOW Item Impact'!$A$5:$A$104&",",D8&","))*'SOW Item Impact'!$D$5:$D$104) -> 27.36 | G8: Design change within existing SOW item | H8: Block milestone payment requests until evidence is uploaded and verified by Legal; generate the filing calendar from deed data; add a titles-in-transit view. | I8: — | J8: 1 | K8: 3 | L8: 0 | M8: 0 | N8: Phase 2 – Build Wave 1 (wk 5–10) | O8: Now — before BRD sign-off (wk 4) | P8: Milestone payment requests require verified evidence; BIR/LGU filing calendar auto-generated at deed signing. | Q8: Requirements Analysis | R8: Payments can still be released before conditions are met. | U8: Open
A9: RE-05 | B9: Project templates and a hard License-to-Sell gate | C9: §3.1 C Project Setup Wizard; launch readiness gate | D9: #9, #10, #11, #12, #13, #14, #15, #33, #37, #70 | E9: 10 | F9: =SUMPRODUCT(ISNUMBER(SEARCH("#"&'SOW Item Impact'!$A$5:$A$104&",",D9&","))*'SOW Item Impact'!$D$5:$D$104) -> 51.84 | G9: Extends SOW scope | H9: Add a template library per project type that clones WBS, cost codes, milestones and documents. Add a permit register, and make DP and License to Sell hard gate criteria that block reservation (#33), not only SO confirmation (#37). | I9: A7 | J9: 2 | K9: 4 | L9: 0 | M9: 0 | N9: Phase 2 – Build Wave 1 (wk 5–10) | O9: Now — before BRD sign-off (wk 4) | P9: Launch gate criteria include DP and License to Sell and are enforced at reservation. | Q9: Change Order | R9: Reservations possible before LTS; project structures remain inconsistent. | U9: Open
A10: RE-06 | B10: One Group cost-code structure | C10: §3.1 G Foundation and data spine (analytic tags, Chart of Accounts) | D10: — | E10: 0 | F10: =SUMPRODUCT(ISNUMBER(SEARCH("#"&'SOW Item Impact'!$A$5:$A$104&",",D10&","))*'SOW Item Impact'!$D$5:$D$104) -> 0 | G10: PHI internal — no AWB effort | H10: No change in effort: configure PHI's Group cost-code structure as the analytic plans, with the analytic account mandatory on every cost line. PHI must hand over the structure before BRD sign-off. | I10: — | J10: 0 | K10: 1 | L10: 0 | M10: 0 | N10: Phase 1 – Discovery & BRD (wk 1–4) | O10: Now — hand over structure before BRD sign-off (wk 4) | P10: Analytic plans follow the Group cost-code structure supplied by PHI; analytic mandatory on all cost lines. | Q10: — | R10: Reports and migration built on the wrong structure; rework after go-live. | U10: Open
A11: RE-07 | B11: Measure construction progress once, use it three times | C11: §3.1 B Construction; F Contracts & retention; D Construction schedule | D11: #30, #66, #67, #68, #69 | E11: 5 | F11: =SUMPRODUCT(ISNUMBER(SEARCH("#"&'SOW Item Impact'!$A$5:$A$104&",",D11&","))*'SOW Item Impact'!$D$5:$D$104) -> 28.8 | G11: Extends SOW scope | H11: Capture % complete per BOQ line on mobile with geotagged photos; use the verified % to drive progress billing (retention, recoupment), unit status (#69) and the POC revenue input. | I11: A6, A3 | J11: 4 | K11: 8 | L11: 0 | M11: 0 | N11: Phase 3 – Build Wave 2 (wk 9–14) | O11: Now — before BRD sign-off (wk 4) | P11: Verified construction progress is the single source for contractor billing, unit construction status and revenue recognition. | Q11: Change Order | R11: Progress keyed three times; billing disputes and revenue lag remain. | U11: Open
A12: RE-08 | B12: Pricing governance and a single price source | C12: §3.1 D Pricing controls; H Pricing rules engine | D12: #49 | E12: 1 | F12: =SUMPRODUCT(ISNUMBER(SEARCH("#"&'SOW Item Impact'!$A$5:$A$104&",",D12&","))*'SOW Item Impact'!$D$5:$D$104) -> 5.76 | G12: Adoption only — configure as scoped | H12: Configure the discount matrix by authority level and scheduled price escalations per phase; publish prices only via the broker portal. | I12: — | J12: 0 | K12: 2 | L12: 0 | M12: 0 | N12: Phase 2 – Build Wave 1 (wk 5–10) | O12: Now — before BRD sign-off (wk 4) | P12: — | Q12: — | R12: Discount leakage continues if the matrix isn't configured. | U12: Open
A13: RE-09 | B13: Digital deal jacket from reservation to CTS | C13: §3.1 A Buyer documents (OCR); H Reservation, buyer portal | D13: #31, #32, #33, #34, #35, #54 | E13: 6 | F13: =SUMPRODUCT(ISNUMBER(SEARCH("#"&'SOW Item Impact'!$A$5:$A$104&",",D13&","))*'SOW Item Impact'!$D$5:$D$104) -> 40.32 | G13: Depends on Appendix A/B gap item | H13: Checklist per financing scheme enforced at reservation; CTS generated from the confirmed SO (A2); notarization batch tracking; reservation-to-CTS SLA dashboard. | I13: A2 | J13: 2 | K13: 4 | L13: 0 | M13: 0 | N13: Phase 2 – Build Wave 1 (wk 5–10) | O13: Now — before BRD sign-off (wk 4) | P13: Buyer document checklist per financing scheme enforced at reservation; CTS generated from the sales order. | Q13: Change Order | R13: Documents still collected in rounds; CTS retyped. | U13: Open
A14: RE-10 | B14: Electronic collections with automatic bank matching | C14: §9 bank statement import (CSV/MT940); §3.3 Customer Portal and Customer Loans | D14: #76, #97 | E14: 2 | F14: =SUMPRODUCT(ISNUMBER(SEARCH("#"&'SOW Item Impact'!$A$5:$A$104&",",D14&","))*'SOW Item Impact'!$D$5:$D$104) -> 17.28 | G14: Design change within existing SOW item | H14: Configure per-buyer payment references and bank-file reconciliation models that match receipts to the buyer ledger, issue the invoice on posting, and queue exceptions. Item #76 becomes proof-of-payment upload plus bank-reference matching — no gateway. | I14: — | J14: 2 | K14: 4 | L14: 3 | M14: 8.64 | N14: Phase 3 – Build Wave 2 (wk 9–14) | O14: Now — before BRD sign-off (wk 4) | P14: Item #76 delivers proof-of-payment upload and bank-reference matching; payment gateway excluded and #76 man-days adjusted. | Q14: — | R14: PHI pays for gateway work in #76 that §9 excludes. | U14: Open
A15: RE-11 | B15: Collections playbook by aging bucket | C15: §3.1 I Collection & aging; loan restructuring | D15: #57, #58, #77, #95, #97, #98 | E15: 6 | F15: =SUMPRODUCT(ISNUMBER(SEARCH("#"&'SOW Item Impact'!$A$5:$A$104&",",D15&","))*'SOW Item Impact'!$D$5:$D$104) -> 34.56 | G15: Depends on Appendix A/B gap item | H15: Automate the aging-bucket playbook: officer assignment at 30 days, restructuring offer via the loan restructuring workflow, demand letters (A5) and the Maceda notice clock (A1). | I15: A1, A5 | J15: 2 | K15: 4 | L15: 0 | M15: 0 | N15: Phase 3 – Build Wave 2 (wk 9–14) | O15: Now — before BRD sign-off (wk 4) | P15: Collections workflow includes aging-bucket assignment, demand letters and statutory Maceda timelines. | Q15: Change Order | R15: Late intervention; avoidable cancellations. | U15: Open
A16: RE-12 | B16: Same-week cancellation and re-listing | C16: §3.1 H Reservation lifecycle; commission clawback | D16: #36, #43 | E16: 2 | F16: =SUMPRODUCT(ISNUMBER(SEARCH("#"&'SOW Item Impact'!$A$5:$A$104&",",D16&","))*'SOW Item Impact'!$D$5:$D$104) -> 18.72 | G16: Depends on Appendix A/B gap item | H16: On top of the Maceda workflow (A1): mandatory cancellation reason codes, automatic re-pricing and re-listing on the effective date. | I16: A1 | J16: 1 | K16: 2 | L16: 0 | M16: 0 | N16: Phase 2 – Build Wave 1 (wk 5–10) | O16: Now — before BRD sign-off (wk 4) | P16: Cancellation workflow captures reason codes and re-lists the lot automatically on the effective date. | Q16: Change Order | R16: Slow inventory recycling; no insight into cancellations. | U16: Open
... A27: RE-23 | B27: Named process owners with KPIs | C27: None | D27: — | E27: 0 | F27: =SUMPRODUCT(ISNUMBER(SEARCH("#"&'SOW Item Impact'!$A$5:$A$104&",",D27&","))*'SOW Item Impact'!$D$5:$D$104) -> 0 | G27: PHI internal — no AWB effort | H27: No AWB effort. Process owners and KPI reviews are PHI governance. | I27: — | J27: 0 | K27: 0 | L27: 0 | M27: 0 | N27: No AWB build | O27: PHI governance — now | P27: — | Q27: — | R27: Improvements fade after go-live. | U27: Open
A28: Total | E28: =SUM(E5:E27) -> 68 | F28: =SUM(F5:F27) -> 429.12 | J28: =SUM(J5:J27) -> 35 | K28: =SUM(K5:K27) -> 73 | L28: =SUM(L5:L27) -> 8 | M28: =SUM(M5:M27) -> 25.16
A29: Dev-days of affected items counts an item once per opportunity that touches it, so the total double counts shared items. Extra effort excludes work already requested in Appendix A.

Sheet SOW Item Impact
A1: SOW §3.3 items — which re-engineering touches each one
A2: Change type: Unchanged · Configure as scoped · Design change at BRD · Extend · Consolidate · Clarify / reduce.
A4: # | B4: Section | C4: Feature | D4: Dev man-days (SOW) | E4: Re-engineering items | F4: Change type | G4: Note for BRD
A5: 1 | B5: Dashboard | C5: Acquisition KPI Cards | D5: 4.32 | F5: Unchanged
A6: 2 | B6: Dashboard | C6: Attention Required List | D6: 5.76 | F6: Unchanged
A7: 3 | B7: Dashboard | C7: Project Progress Bars | D7: 2.88 | F7: Unchanged
A8: 4 | B8: Dashboard | C8: Quick Navigation | D8: 2.88 | F8: Unchanged
A9: 5 | B9: Dashboard | C9: Lot Inventory | D9: 5.76 | F9: Unchanged
A10: 6 | B10: Dashboard | C10: Project | D10: 4.32 | F10: Unchanged
A11: 7 | B11: Projects & Pipeline | C11: Project Consolidated View | D11: 5.76 | E11: RE-03 | F11: Design change at BRD
A12: 8 | B12: Projects & Pipeline | C12: Project Search & Filters | D12: 4.32 | F12: Unchanged
A13: 9 | B13: Project Setup Wizard | C13: Step 2 - Site Details | D13: 4.32 | E13: RE-05 | F13: Extend
A14: 10 | B14: Project Setup Wizard | C14: Step 3 - Targets | D14: 4.32 | E14: RE-05 | F14: Extend
A15: 11 | B15: Project Setup Wizard | C15: Step 4 - Team Assignment | D15: 4.32 | E15: RE-05 | F15: Extend
A16: 12 | B16: Project Setup Wizard | C16: Step 5 - Milestone Template | D16: 5.76 | E16: RE-05 | F16: Extend
A17: 13 | B17: Project Setup Wizard | C17: Step 6 - Documents | D17: 4.32 | E17: RE-05 | F17: Extend
A18: 14 | B18: Project Setup Wizard | C18: Step 7 - Review & Launch | D18: 4.32 | E18: RE-05 | F18: Extend
A19: 15 | B19: Project Setup Wizard | C19: Sample Form Previews | D19: 4.32 | E19: RE-05 | F19: Extend
A20: 16 | B20: Lot Onboarding Form | C20: Lot Master Data | D20: 5.76 | F20: Unchanged
A21: 17 | B21: Lot Onboarding Form | C21: Pricing & Source | D21: 4.32 | F21: Unchanged
A22: 18 | B22: Lot Onboarding Form | C22: Seller/Owner Details | D22: 4.32 | F22: Unchanged
A23: 19 | B23: Lot Onboarding Form | C23: Attachments Checklist | D23: 4.32 | F23: Unchanged
A24: 20 | B24: Lot Onboarding Form | C24: Auto Due-Diligence Checklist | D24: 7.2 | E24: RE-03 | F24: Design change at BRD
A25: 21 | B25: Lot Onboarding Form | C25: Approval Route | D25: 5.76 | E25: RE-02, RE-03 | F25: Design change at BRD
A26: 22 | B26: Lot Onboarding Form | C26: Bulk Lot Onboarding Wizard | D26: 7.2 | F26: Unchanged
A27: 23 | B27: Acquisition & Payments (Multi-Owner) | C27: Multi-Owner Land Sources | D27: 8.64 | F27: Unchanged
A28: 24 | B28: Acquisition & Payments (Multi-Owner) | C28: Per-Owner Milestone Schedule | D28: 8.64 | E28: RE-04 | F28: Design change at BRD
A29: 25 | B29: Acquisition & Payments (Multi-Owner) | C29: Auto-Drafted Deed of Absolute Sale | D29: 8.64 | F29: Unchanged
A30: 26 | B30: Acquisition & Payments (Multi-Owner) | C30: BIR / LGU Filing Tracker | D30: 7.2 | E30: RE-04 | F30: Design change at BRD
A31: 27 | B31: Lot Detail & Lifecycle | C31: Lot Lock / Reusable Pill | D31: 4.32 | F31: Unchanged
A32: 28 | B32: Lot Detail & Lifecycle | C32: Locked Ribbon & Kanban Lock Icons | D32: 4.32 | F32: Unchanged
A33: 29 | B33: Lot Detail & Lifecycle | C33: Title Tab | D33: 5.76 | E33: RE-04, RE-18 | F33: Design change at BRD
A34: 30 | B34: Lot Detail & Lifecycle | C34: DD / Milestones / Construction Tabs | D34: 7.2 | E34: RE-07 | F34: Extend
A35: 31 | B35: CRM → Reservation → Sales Order | C35: Lot Interest & Availability Browser | D35: 7.2 | E35: RE-09 | F35: Design change at BRD
A36: 32 | B36: CRM → Reservation → Sales Order | C36: Reserve Lot from Opportunity | D36: 7.2 | E36: RE-09 | F36: Design change at BRD
A37: 33 | B37: CRM → Reservation → Sales Order | C37: Soft-Hold with Expiry (Reservation) | D37: 7.2 | E37: RE-05, RE-09 | F37: Add LTS block | G37: Reservation blocked when DP or License to Sell missing (RE-05).
A38: 34 | B38: CRM → Reservation → Sales Order | C38: Reservation Fee Payment & Receipt | D38: 7.2 | E38: RE-09 | F38: Design change at BRD
A39: 35 | B39: CRM → Reservation → Sales Order | C39: Opportunity Won → Auto-Create Sales Order | D39: 7.2 | E39: RE-09 | F39: Design change at BRD
A40: 36 | B40: CRM → Reservation → Sales Order | C40: SO Confirm / Lot Lock Flow | D40: 7.2 | E40: RE-12 | F40: Design change at BRD
A41: 37 | B41: CRM → Reservation → Sales Order | C41: Launch-Readiness Gate on SO Confirm | D41: 5.76 | E41: RE-05 | F41: Change gate point to reservation | G41: Gate must block reservation, not only SO confirmation (RE-05).
...

Sheet SOW Phase Timeline
A1: When each re-engineering decision lands in the SOW timeline
A2: Decisions must be in the BRD before Phase 1 ends; build happens in the SOW wave for the affected module.
A4: SOW phase | B4: Weeks | C4: Re-engineering items built or loaded here | D4: What PHI must have ready
A5: Phase 1 – Discovery & BRD (wk 1–4) | B5: 1–4 | C5: Decisions for all items; cost-code structure (RE-06) | D5: Board-approved DOA matrix, Group cost codes, pricing policy, collections playbook, TORC definition, KPI dictionary
A6: Phase 2 – Build Wave 1 (wk 5–10) | B6: 5–10 | C6: RE-02 One digital Delegation of Authority matrix, RE-03 Two-stage land due diligence with deal scorecard, RE-04 Evidence-based land payments and filing calendar, RE-05 Project templates and a hard License-to-Sell gate, RE-08 Pricing governance and a single price source, RE-09 Digital deal jacket from reservation to CTS, RE-12 Same-week cancellation and re-listing, RE-14 Hands-off commission cycle | D6: BRD-signed specifications for land, inventory, reservation and sales changes
A7: Phase 3 – Build Wave 2 (wk 9–14) | B7: 9–14 | C7: RE-01 Driver-based budget with commitment control, RE-07 Measure construction progress once, use it three times, RE-10 Electronic collections with automatic bank matching, RE-11 Collections playbook by aging bucket, RE-13 Start loan takeout at reservation, RE-15 No PO, no pay — with scheduled payment runs, RE-16 Independent vendor master with bank-change verification, RE-17 TORC paid directly, recharged automatically, RE-18 One handover pipeline from RFO to title, RE-19 Automated monthly revenue recognition, RE-20 Fast close and one management pack, RE-21 Rolling 13-week cash forecast | D7: Specifications for construction, supplier, finance and customer-servicing changes; auditor-agreed POC method
A8: Phase 4 – Migration & SIT (wk 13–16) | B8: 13–16 | C8: RE-22 Data ownership and clean-up before migration | D8: Cleansed legacy data passing mock loads; reconciled opening balances
A9: Phase 5 – UAT & Training (wk 16–18) | B9: 16–18 | C9: All items tested in UAT scripts | D9: Process owners test the re-engineered flows, not the old ones
A10: No AWB build | B10: — | C10: RE-23 Named process owners with KPIs | D10: Process owners and KPI review cycle (PHI governance)
