Workbook

Sheet README
A1: PHI Enterprise Process Blueprint — Odoo 19 (Rev. C)
A3: Purpose | B3: Master blueprint of PHI processes, data and hand-offs for the Odoo 19 BRD with the implementation vendor. Companion to the published HTML blueprint and the .bpmn diagram files.
A4: Basis | B4: Enterprise ERP Business Reference Flow (Budget Setup). Process numbers 04, 14, 15, 16, 18, 19 come from that flow; the rest are proposed.
A5: Key decisions reflected | B5: Vendor proposes the Lot as the master model for each sellable unit. TORC = taxes and other related charges.
A6: Sheets | B6: Fit Summary · Process Catalogue · SIPOC · COPIS · Data Matrix · Master Data · Lot Touchpoints · Open Items · SOW Gap Analysis · SOW Scope Map · SOW Effort Check · SOW Observations
A7: Yellow cells | B7: Input columns for process owners: validation status, owner comments, decisions. Everything else is blueprint content — change it only through a revision.
A8: Example input | B8: Data Matrix row 09.1 → Validated = "Yes – with changes"; Owner comments = "Reservation validity is 30 days, not 15; add promo code field."
A9: Fit legend | B9: Standard = works out of the box · Configure = setup, Studio fields, rules · Extend = likely custom module, scope with vendor
A10: Caveat | B10: Odoo app placement and fit are indicative starting positions for fit-gap, not vendor commitments. Statutory items (RA 6552, PD 957, EOPT, PFRS 15) to be confirmed by Legal, Tax and the external auditor.
A11: SOW reviewed | B11: Achieve Without Borders SOW S343096, Odoo v19 Enterprise, vendor-signed 24 Sep 2026 (739 person-days, PHP 7,090,000 ex-VAT after discount).
A12: Deferred scope | B12: Leasing (10) and property management / HOA (18) are deferred to a later phase by PHI decision; they stay in the blueprint but are excluded from the SOW negotiation.

Sheet Fit Summary
A1: Domain | B1: Standard | C1: Configure | D1: Extend | E1: Total steps | F1: % Extend
A2: Plan & fund | B2: =SUMPRODUCT(('Process Catalogue'!$D$2:$D$22=$A2)*COUNTIFS('Data Matrix'!$B$2:$B$35,'Process Catalogue'!$A$2:$A$22,'Data Matrix'!$I$2:$I$35,"Standard")) -> 1 | C2: =SUMPRODUCT(('Process Catalogue'!$D$2:$D$22=$A2)*COUNTIFS('Data Matrix'!$B$2:$B$35,'Process Catalogue'!$A$2:$A$22,'Data Matrix'!$I$2:$I$35,"Configure")) -> 4 | D2: =SUMPRODUCT(('Process Catalogue'!$D$2:$D$22=$A2)*COUNTIFS('Data Matrix'!$B$2:$B$35,'Process Catalogue'!$A$2:$A$22,'Data Matrix'!$I$2:$I$35,"Extend")) -> 0 | E2: =SUM(B2:D2) -> 5 | F2: =IF(E2=0,0,D2/E2) -> 0
A3: Land | B3: =SUMPRODUCT(('Process Catalogue'!$D$2:$D$22=$A3)*COUNTIFS('Data Matrix'!$B$2:$B$35,'Process Catalogue'!$A$2:$A$22,'Data Matrix'!$I$2:$I$35,"Standard")) -> 0 | C3: =SUMPRODUCT(('Process Catalogue'!$D$2:$D$22=$A3)*COUNTIFS('Data Matrix'!$B$2:$B$35,'Process Catalogue'!$A$2:$A$22,'Data Matrix'!$I$2:$I$35,"Configure")) -> 0 | D3: =SUMPRODUCT(('Process Catalogue'!$D$2:$D$22=$A3)*COUNTIFS('Data Matrix'!$B$2:$B$35,'Process Catalogue'!$A$2:$A$22,'Data Matrix'!$I$2:$I$35,"Extend")) -> 3 | E3: =SUM(B3:D3) -> 3 | F3: =IF(E3=0,0,D3/E3) -> 1
A4: Project & inventory | B4: =SUMPRODUCT(('Process Catalogue'!$D$2:$D$22=$A4)*COUNTIFS('Data Matrix'!$B$2:$B$35,'Process Catalogue'!$A$2:$A$22,'Data Matrix'!$I$2:$I$35,"Standard")) -> 0 | C4: =SUMPRODUCT(('Process Catalogue'!$D$2:$D$22=$A4)*COUNTIFS('Data Matrix'!$B$2:$B$35,'Process Catalogue'!$A$2:$A$22,'Data Matrix'!$I$2:$I$35,"Configure")) -> 1 | D4: =SUMPRODUCT(('Process Catalogue'!$D$2:$D$22=$A4)*COUNTIFS('Data Matrix'!$B$2:$B$35,'Process Catalogue'!$A$2:$A$22,'Data Matrix'!$I$2:$I$35,"Extend")) -> 3 | E4: =SUM(B4:D4) -> 4 | F4: =IF(E4=0,0,D4/E4) -> 0.75
A5: Sales & leasing | B5: =SUMPRODUCT(('Process Catalogue'!$D$2:$D$22=$A5)*COUNTIFS('Data Matrix'!$B$2:$B$35,'Process Catalogue'!$A$2:$A$22,'Data Matrix'!$I$2:$I$35,"Standard")) -> 0 | C5: =SUMPRODUCT(('Process Catalogue'!$D$2:$D$22=$A5)*COUNTIFS('Data Matrix'!$B$2:$B$35,'Process Catalogue'!$A$2:$A$22,'Data Matrix'!$I$2:$I$35,"Configure")) -> 2 | D5: =SUMPRODUCT(('Process Catalogue'!$D$2:$D$22=$A5)*COUNTIFS('Data Matrix'!$B$2:$B$35,'Process Catalogue'!$A$2:$A$22,'Data Matrix'!$I$2:$I$35,"Extend")) -> 4 | E5: =SUM(B5:D5) -> 6 | F5: =IF(E5=0,0,D5/E5) -> 0.66666667
A6: Accounts monitoring & financing | B6: =SUMPRODUCT(('Process Catalogue'!$D$2:$D$22=$A6)*COUNTIFS('Data Matrix'!$B$2:$B$35,'Process Catalogue'!$A$2:$A$22,'Data Matrix'!$I$2:$I$35,"Standard")) -> 0 | C6: =SUMPRODUCT(('Process Catalogue'!$D$2:$D$22=$A6)*COUNTIFS('Data Matrix'!$B$2:$B$35,'Process Catalogue'!$A$2:$A$22,'Data Matrix'!$I$2:$I$35,"Configure")) -> 1 | D6: =SUMPRODUCT(('Process Catalogue'!$D$2:$D$22=$A6)*COUNTIFS('Data Matrix'!$B$2:$B$35,'Process Catalogue'!$A$2:$A$22,'Data Matrix'!$I$2:$I$35,"Extend")) -> 5 | E6: =SUM(B6:D6) -> 6 | F6: =IF(E6=0,0,D6/E6) -> 0.83333333
A7: Delivery & property management | B7: =SUMPRODUCT(('Process Catalogue'!$D$2:$D$22=$A7)*COUNTIFS('Data Matrix'!$B$2:$B$35,'Process Catalogue'!$A$2:$A$22,'Data Matrix'!$I$2:$I$35,"Standard")) -> 0 | C7: =SUMPRODUCT(('Process Catalogue'!$D$2:$D$22=$A7)*COUNTIFS('Data Matrix'!$B$2:$B$35,'Process Catalogue'!$A$2:$A$22,'Data Matrix'!$I$2:$I$35,"Configure")) -> 5 | D7: =SUMPRODUCT(('Process Catalogue'!$D$2:$D$22=$A7)*COUNTIFS('Data Matrix'!$B$2:$B$35,'Process Catalogue'!$A$2:$A$22,'Data Matrix'!$I$2:$I$35,"Extend")) -> 1 | E7: =SUM(B7:D7) -> 6 | F7: =IF(E7=0,0,D7/E7) -> 0.16666667
A8: Accounts payable | B8: =SUMPRODUCT(('Process Catalogue'!$D$2:$D$22=$A8)*COUNTIFS('Data Matrix'!$B$2:$B$35,'Process Catalogue'!$A$2:$A$22,'Data Matrix'!$I$2:$I$35,"Standard")) -> 2 | C8: =SUMPRODUCT(('Process Catalogue'!$D$2:$D$22=$A8)*COUNTIFS('Data Matrix'!$B$2:$B$35,'Process Catalogue'!$A$2:$A$22,'Data Matrix'!$I$2:$I$35,"Configure")) -> 0 | D8: =SUMPRODUCT(('Process Catalogue'!$D$2:$D$22=$A8)*COUNTIFS('Data Matrix'!$B$2:$B$35,'Process Catalogue'!$A$2:$A$22,'Data Matrix'!$I$2:$I$35,"Extend")) -> 0 | E8: =SUM(B8:D8) -> 2 | F8: =IF(E8=0,0,D8/E8) -> 0
A9: Forecasts & KPIs | B9: =SUMPRODUCT(('Process Catalogue'!$D$2:$D$22=$A9)*COUNTIFS('Data Matrix'!$B$2:$B$35,'Process Catalogue'!$A$2:$A$22,'Data Matrix'!$I$2:$I$35,"Standard")) -> 0 | C9: =SUMPRODUCT(('Process Catalogue'!$D$2:$D$22=$A9)*COUNTIFS('Data Matrix'!$B$2:$B$35,'Process Catalogue'!$A$2:$A$22,'Data Matrix'!$I$2:$I$35,"Configure")) -> 2 | D9: =SUMPRODUCT(('Process Catalogue'!$D$2:$D$22=$A9)*COUNTIFS('Data Matrix'!$B$2:$B$35,'Process Catalogue'!$A$2:$A$22,'Data Matrix'!$I$2:$I$35,"Extend")) -> 0 | E9: =SUM(B9:D9) -> 2 | F9: =IF(E9=0,0,D9/E9) -> 0
A10: Total | B10: =SUM(B2:B9) -> 3 | C10: =SUM(C2:C9) -> 15 | D10: =SUM(D2:D9) -> 16 | E10: =SUM(E2:E9) -> 34 | F10: =IF(E10=0,0,D10/E10) -> 0.47058824
A12: Counts come from the Data Matrix Fit column, grouped by each process's domain in Process Catalogue.

Sheet Process Catalogue
A1: Proc ID | B1: Process | C1: Value-chain stage | D1: Domain | E1: Accountable owner | F1: Indicative Odoo 19 home | G1: Fit | H1: Numbered in reference flow? | I1: Owner confirmed (Y/N) | J1: Comments
A2: 01 | B2: Budget setup (corporate & project) | C2: Plan & fund | D2: Plan & fund | E2: Finance – budget & FP&A | F2: Accounting › Budgets, Analytic plans; Approvals; Spreadsheet | G2: Configure | H2: Proposed
A3: 02 | B3: Corporate & project financing | C3: Plan & fund | D3: Plan & fund | E3: Treasury | F3: Accounting (bank, loans, journals); Documents | G3: Configure | H3: Proposed
A4: 03 | B4: Corporate expenses | C4: Plan & fund | D4: Plan & fund | E4: Administration / requesting departments | F4: Purchase; Approvals; Expenses; Accounting | G4: Standard | H4: Proposed
A5: 04 | B5: Land acquisition | C5: Acquire land | D5: Land | E5: Land acquisition / business development | F5: Documents; Sign; Approvals; Purchase / Accounting (milestones); custom land register | G5: Extend | H5: Yes
A6: 05 | B6: Project setup & project financing | C6: Develop | D6: Project & inventory | E6: Project Development | F6: Project; Accounting (analytic accounts); Documents; custom permit tracker | G6: Configure | H6: Proposed
A7: 06 | B7: Project expenses & construction (milestone-based) | C7: Develop | D7: Project & inventory | E7: Construction / cost control | F7: Purchase; Project; Accounting; progress-billing extension | G7: Extend | H7: Proposed
A8: 07 | B8: Inventory & financing options setup | C8: Develop | D8: Project & inventory | E8: Sales admin / Project Development | F8: Lot master model (vendor-proposed) linked to Sales products, pricelists and payment terms; Studio | G8: Extend | H8: Proposed
A9: 08 | B9: Sales channel accreditation | C9: Stock & sell | D9: Sales & leasing | E9: Sales admin | F9: Contacts; Documents; Sign; Approvals; Sales commission plans | G9: Configure | H9: Proposed
A10: 09 | B10: Sales (reservation to contract to sell) | C10: Stock & sell | D10: Sales & leasing | E10: Sales / sales admin | F10: CRM; Sales; Sign; Documents; Accounting; custom sales computation | G10: Extend | H10: Proposed
A11: 10 | B11: Leasing | C11: Stock & sell | D11: Sales & leasing | E11: Leasing / sales | F11: Rental or Subscriptions; Sign; Accounting | G11: Configure | H11: Proposed
A12: 11 | B12: Accounts monitoring (documentation, receipting, collection) | C12: Collect & finance | D12: Accounts monitoring & financing | E12: Credit & collection | F12: Accounting (invoicing, payments, follow-up); Documents; PH localization; custom amortization & penalty engine | G12: Extend | H12: Proposed
A13: 12 | B13: Cancellations & return to inventory | C13: Collect & finance | D13: Accounts monitoring & financing | E13: Credit & collection / Legal | F13: Accounting; Approvals; custom Maceda calculator | G13: Extend | H13: Proposed
... A22: X2 | B22: KPIs & variance reports | C22: Cross-cutting | D22: Forecasts & KPIs | E22: Finance – FP&A | F22: Accounting budget reports; Spreadsheet dashboards; BI | G22: Configure | H22: Proposed

Sheet SIPOC
A1: Proc ID | B1: Process | C1: Suppliers | D1: Inputs | E1: Process steps | F1: Outputs | G1: Customers | H1: Owner | I1: Owner comments
A2: 01 | B2: Budget setup (corporate & project) | C2: • ManCom / Executive • Department heads • Project Development • Finance – FP&A • Treasury | D2: • Strategic plan and targets • Prior-year actuals • Project feasibility studies • Sales, collection and cash forecasts • Chart of accounts and analytic structure | E2: 1. Define budget structure (accounts × analytic plans: company, project, phase, cost center) 2. Annual corporate budget planning 3. Project (life-of-project) budget by phase and cost code 4. Consolidate and review 5. Approve and lock baseline; switch on budget checks | F2: • Approved corporate budget • Approved project budget baselines • Budget-control rules • Forecast baseline | G2: • All spending departments • Accounting and Procurement • ManCom / Board • Lenders | H2: Finance – budget & FP&A
A3: 02 | B3: Corporate & project financing | C3: • Banks and lenders • Shareholders • Treasury • ManCom | D3: • Cash-flow forecast • Approved budgets • Term sheets and loan agreements • Collateral documents | E3: 1. Identify funding need 2. Negotiate facility; Board approval 3. Drawdown and allocate to company / project 4. Accrue and capitalize interest where allowed 5. Schedule debt service | F3: • Loan records and amortization schedules • Funds availability per project • Interest accruals (expensed or capitalized) | G3: • Projects • Accounts payable (loan payments) • Accounting • Lenders | H3: Treasury
A4: 03 | B4: Corporate expenses | C4: • Departments (admin, branding, executive, HR) • Suppliers and service providers | D4: • Approved department budget • Purchase requests • Quotations and contracts | E4: 1. Raise request 2. Budget check 3. Approve 4. Issue PO or contract 5. Receive and accept 6. Send bill to AP | F4: • POs and committed cost • Vendor bills • Expense by cost center | G4: • Accounts payable • Accounting • Department heads | H4: Administration / requesting departments
A5: 04 | B5: Land acquisition | C5: • Landowners, heirs, land brokers • Appraisers and surveyors • Legal • BIR, Registry of Deeds, LGU assessor | D5: • Land offers • Title, tax declaration, survey, zoning • Appraisal • Acquisition budget and ManCom approval | E5: 1. Source and log opportunity 2. Due diligence 3. Negotiate and execute agreement (deed, CTS or JV) 4. Pay per milestones 5. Pay CGT/DST/transfer tax and transfer title 6. Book land to project or land bank | F5: • Executed agreements • Milestone payments • Title in PHI's name • Capitalized land cost; land bank record | G5: • Project Development • Accounting • Treasury • Legal | H5: Land acquisition / business development
A6: 05 | B6: Project setup & project financing | C6: • Project Development • Architects and engineers • Finance and Treasury • LGU, DENR, DHSUD | D6: • Approved project budget • Master plan and phasing • Land title • Permits: DP, ECC, BP, CR/LTS | E6: 1. Create project master and analytic account 2. Define phases, blocks/towers and WBS 3. Set milestones 4. Secure project financing 5. Track permits and License to Sell | F6: • Project master data • WBS and milestones • Project funding lines • License-to-sell status | G6: • Construction • Sales • Accounting • Inventory | H6: Project Development
A7: 06 | B7: Project expenses & construction (milestone-based) | C7: • Contractors and subcontractors • Suppliers • Engineering and QS • Planning, permits, titling, marketing, sales, loan-interest cost owners | D7: • Project budget and WBS • Contracts and BOQ • Accomplishment reports • Variation orders | E7: 1. Award contract / issue PO 2. Verify accomplishment by milestone 3. Process progress billing with retention and recoupment 4. Send to AP 5. Update % completion | F7: • Committed vs actual cost • % completion per unit/phase • Retention payable • Construction-in-progress cost | G7: • Accounts payable • Accounting (POC revenue) • Inventory (unit status) • ManCom | H7: Construction / cost control
A8: 07 | B8: Inventory & financing options setup | C8: • Project Development • Construction • Finance • Sales admin | D8: • Approved subdivision / condo plans • Unit list, areas, models • Price list and escalation rules • Financing schemes | E8: 1. Create lots as the unit master (project-phase-block-lot; tower-floor-unit for condos) 2. Set price lists 3. Track construction status: pre-construction → construction → ready 4. Track sales status: available → reserved → sold / hold / cancelled 5. Configure financing options and payment-term templates | F8: • Sellable inventory • Price lists • Payment-term templates • Availability board | G8: • Sales channels • Accounts monitoring • Finance | H8: Sales admin / Project Development
A9: 08 | B9: Sales channel accreditation | C9: • Realty firms • Sales agents • Legal | D9: • Accreditation application • PRC license, DHSUD registration • BIR COR (Form 2303), TIN • Accreditation agreement | E9: 1. Receive application 2. Verify documents 3. Approve 4. Create partner record and assign commission scheme 5. Renew before expiry | F9: • Accredited broker/agent master • Commission schemes • Validity dates | G9: • Sales • Accounts payable (commissions) • Marketing | H9: Sales admin
A10: 09 | B10: Sales (reservation to contract to sell) | C10: • Buyers and co-borrowers • Brokers and agents • Marketing • Credit & collection | D10: • Available unit • Price list, promos, discounts • Financing scheme • Buyer KYC documents • Reservation fee | E10: 1. Prepare sales computation 2. Reserve unit and receive reservation fee 3. Collect documents; credit check 4. Generate CTS and payment schedule 5. Sign and notarize CTS; tag unit sold | F10: • Reservation agreement • CTS (contract to sell) • Payment schedule • Buyer master • Commission accrual | G10: • Buyer • Accounts monitoring • Accounting • Brokers | H10: Sales / sales admin
A11: 10 | B11: Leasing | C11: • Tenants • Leasing team • Legal | D11: • Lease-available unit • Lease rate and term sheet • Security deposit, advance rent | E11: 1. Issue term sheet 2. Approve 3. Sign lease contract 4. Bill rent, CUSA and utilities 5. Renew or terminate | F11: • Lease contracts • Recurring invoices • Deposit liability | G11: • Tenants • Accounting • Property management | H11: Leasing / sales
A12: 11 | B12: Accounts monitoring (documentation, receipting, collection) | C12: • Buyers • Cashier • Sales admin • Banks (PDCs, transfers) | D12: • Signed CTS and payment schedule • Payments: cash, check, PDC, bank transfer, online • Buyer documents | E12: 1. Manage contracts and documents 2. Issue BIR-compliant invoice / receipt 3. Post and allocate collections 4. Issue SOA 5. Compute delinquency and penalties 6. Produce aging | F12: • Posted collections • Invoices / receipts • SOA • Penalties and aging • Delinquency list | G12: • Buyers • Accounting • Treasury • ManCom | H12: Credit & collection
A13: 12 | B13: Cancellations & return to inventory | C13: • Buyer (voluntary) • Credit & collection (default) • Legal | D13: • Cancellation request or default status • Payment history • Years of installments paid | E13: 1. Observe grace period 2. Serve notarial notice 3. Compute cash surrender value or forfeiture 4. Approve 5. Reverse receivable, revenue and commission 6. Refund via AP; return unit | F13: • Cancellation record • Refund payable or forfeiture income • Unit back to available | G13: • Buyer • Accounts payable • Accounting • Sales / inventory | H13: Credit & collection / Legal
... A22: X2 | B22: KPIs & variance reports | C22: • All processes | D22: • Budgets and actuals by analytic account • Sales and collection data • Construction progress | E22: 1. Close period 2. Compute KPIs 3. Explain variances 4. Review with owners | F22: • Budget vs actual • Absorption and sales velocity • Collection efficiency and aging • Cost variance | G22: • ManCom • Board • Process owners | H22: Finance – FP&A

Sheet COPIS
A1: COPIS — customer-first view of each process
A2: Same content as SIPOC, read from the customer backwards: who is served, what they receive, how it is produced, what it needs, and who supplies it.
A4: Proc ID | B4: Process | C4: Customers | D4: Outputs | E4: Process steps | F4: Inputs | G4: Suppliers | H4: Customer requirement (validate with customer)
A5: L0 | B5: Enterprise (PHI) | C5: • Homebuyers and co-borrowers • Tenants • Homeowners' associations • Shareholders and ManCom • Lenders, regulators, auditors | D5: • Completed houses, lots and condo units • Titles in buyers' names • Managed communities, HOA turnover • Collections, revenue, returns • Statutory reports and BIR filings | E5: 1. Plan & fund 2. Acquire land 3. Develop 4. Stock & sell 5. Collect & finance 6. Deliver & manage 7. Pay & measure | F5: • Land and titles • Capital and loans • Materials, labor, permits • Market demand, buyer payments • Policies and regulations | G5: • Landowners, JV partners • Banks, Pag-IBIG, shareholders • Contractors and suppliers • Accredited brokers and agents • BIR, RD, LGUs, DHSUD, DENR
A6: 01 | B6: Budget setup (corporate & project) | C6: • All spending departments • Accounting and Procurement • ManCom / Board • Lenders | D6: • Approved corporate budget • Approved project budget baselines • Budget-control rules • Forecast baseline | E6: 1. Define budget structure (accounts × analytic plans: company, project, phase, cost center) 2. Annual corporate budget planning 3. Project (life-of-project) budget by phase and cost code 4. Consolidate and review 5. Approve and lock baseline; switch on budget checks | F6: • Strategic plan and targets • Prior-year actuals • Project feasibility studies • Sales, collection and cash forecasts • Chart of accounts and analytic structure | G6: • ManCom / Executive • Department heads • Project Development • Finance – FP&A • Treasury
A7: 02 | B7: Corporate & project financing | C7: • Projects • Accounts payable (loan payments) • Accounting • Lenders | D7: • Loan records and amortization schedules • Funds availability per project • Interest accruals (expensed or capitalized) | E7: 1. Identify funding need 2. Negotiate facility; Board approval 3. Drawdown and allocate to company / project 4. Accrue and capitalize interest where allowed 5. Schedule debt service | F7: • Cash-flow forecast • Approved budgets • Term sheets and loan agreements • Collateral documents | G7: • Banks and lenders • Shareholders • Treasury • ManCom
A8: 03 | B8: Corporate expenses | C8: • Accounts payable • Accounting • Department heads | D8: • POs and committed cost • Vendor bills • Expense by cost center | E8: 1. Raise request 2. Budget check 3. Approve 4. Issue PO or contract 5. Receive and accept 6. Send bill to AP | F8: • Approved department budget • Purchase requests • Quotations and contracts | G8: • Departments (admin, branding, executive, HR) • Suppliers and service providers
A9: 04 | B9: Land acquisition | C9: • Project Development • Accounting • Treasury • Legal | D9: • Executed agreements • Milestone payments • Title in PHI's name • Capitalized land cost; land bank record | E9: 1. Source and log opportunity 2. Due diligence 3. Negotiate and execute agreement (deed, CTS or JV) 4. Pay per milestones 5. Pay CGT/DST/transfer tax and transfer title 6. Book land to project or land bank | F9: • Land offers • Title, tax declaration, survey, zoning • Appraisal • Acquisition budget and ManCom approval | G9: • Landowners, heirs, land brokers • Appraisers and surveyors • Legal • BIR, Registry of Deeds, LGU assessor
A10: 05 | B10: Project setup & project financing | C10: • Construction • Sales • Accounting • Inventory | D10: • Project master data • WBS and milestones • Project funding lines • License-to-sell status | E10: 1. Create project master and analytic account 2. Define phases, blocks/towers and WBS 3. Set milestones 4. Secure project financing 5. Track permits and License to Sell | F10: • Approved project budget • Master plan and phasing • Land title • Permits: DP, ECC, BP, CR/LTS | G10: • Project Development • Architects and engineers • Finance and Treasury • LGU, DENR, DHSUD
A11: 06 | B11: Project expenses & construction (milestone-based) | C11: • Accounts payable • Accounting (POC revenue) • Inventory (unit status) • ManCom | D11: • Committed vs actual cost • % completion per unit/phase • Retention payable • Construction-in-progress cost | E11: 1. Award contract / issue PO 2. Verify accomplishment by milestone 3. Process progress billing with retention and recoupment 4. Send to AP 5. Update % completion | F11: • Project budget and WBS • Contracts and BOQ • Accomplishment reports • Variation orders | G11: • Contractors and subcontractors • Suppliers • Engineering and QS • Planning, permits, titling, marketing, sales, loan-interest cost owners
A12: 07 | B12: Inventory & financing options setup | C12: • Sales channels • Accounts monitoring • Finance | D12: • Sellable inventory • Price lists • Payment-term templates • Availability board | E12: 1. Create lots as the unit master (project-phase-block-lot; tower-floor-unit for condos) 2. Set price lists 3. Track construction status: pre-construction → construction → ready 4. Track sales status: available → reserved → sold / hold / cancelled 5. Configure financing options and payment-term templates | F12: • Approved subdivision / condo plans • Unit list, areas, models • Price list and escalation rules • Financing schemes | G12: • Project Development • Construction • Finance • Sales admin
A13: 08 | B13: Sales channel accreditation | C13: • Sales • Accounts payable (commissions) • Marketing | D13: • Accredited broker/agent master • Commission schemes • Validity dates | E13: 1. Receive application 2. Verify documents 3. Approve 4. Create partner record and assign commission scheme 5. Renew before expiry | F13: • Accreditation application • PRC license, DHSUD registration • BIR COR (Form 2303), TIN • Accreditation agreement | G13: • Realty firms • Sales agents • Legal
A14: 09 | B14: Sales (reservation to contract to sell) | C14: • Buyer • Accounts monitoring • Accounting • Brokers | D14: • Reservation agreement • CTS (contract to sell) • Payment schedule • Buyer master • Commission accrual | E14: 1. Prepare sales computation 2. Reserve unit and receive reservation fee 3. Collect documents; credit check 4. Generate CTS and payment schedule 5. Sign and notarize CTS; tag unit sold | F14: • Available unit • Price list, promos, discounts • Financing scheme • Buyer KYC documents • Reservation fee | G14: • Buyers and co-borrowers • Brokers and agents • Marketing • Credit & collection
A15: 10 | B15: Leasing | C15: • Tenants • Accounting • Property management | D15: • Lease contracts • Recurring invoices • Deposit liability | E15: 1. Issue term sheet 2. Approve 3. Sign lease contract 4. Bill rent, CUSA and utilities 5. Renew or terminate | F15: • Lease-available unit • Lease rate and term sheet • Security deposit, advance rent | G15: • Tenants • Leasing team • Legal
A16: 11 | B16: Accounts monitoring (documentation, receipting, collection) | C16: • Buyers • Accounting • Treasury • ManCom | D16: • Posted collections • Invoices / receipts • SOA • Penalties and aging • Delinquency list | E16: 1. Manage contracts and documents 2. Issue BIR-compliant invoice / receipt 3. Post and allocate collections 4. Issue SOA 5. Compute delinquency and penalties 6. Produce aging | F16: • Signed CTS and payment schedule • Payments: cash, check, PDC, bank transfer, online • Buyer documents | G16: • Buyers • Cashier • Sales admin • Banks (PDCs, transfers)
... A26: X2 | B26: KPIs & variance reports | C26: • ManCom • Board • Process owners | D26: • Budget vs actual • Absorption and sales velocity • Collection efficiency and aging • Cost variance | E26: 1. Close period 2. Compute KPIs 3. Explain variances 4. Review with owners | F26: • Budgets and actuals by analytic account • Sales and collection data • Construction progress | G26: • All processes

Sheet Data Matrix
A1: Ref | B1: Proc ID | C1: Process | D1: Step | E1: a. Trigger event | F1: b. Inputs & data fields | G1: c. System hand-off | H1: d. Exceptions / edge cases | I1: Fit | J1: Owner | K1: Validated | L1: Owner comments
A2: 01.1 | B2: 01 | C2: Budget setup (corporate & project) | D2: Define budget structure | E2: Budget cycle opens (timer, prior-year Q3) | F2: Fiscal year; company; account; analytic plans (business unit, project, phase, cost center, expense type); budget version; currency | G2: Accounting › Analytic plans → Budgets; templates out to Spreadsheet | H2: New project mid-year needs lines; COA changes after load; intercompany charges across PHI entities | I2: Configure | J2: Finance – budget & FP&A
A3: 01.2 | B3: 01 | C3: Budget setup (corporate & project) | D3: Corporate budget approval | E3: Templates issued to departments | F3: Department; account; monthly amounts; justification; prior-year actual; version; approver; approval date | G3: Spreadsheet import → Budget (draft) → Approvals → Budget (confirmed) → budget check on PR/PO/bill | H3: Realignment between lines; supplemental budget; rejected versions kept for audit; approved over-budget override | I3: Configure | J3: Finance – budget & FP&A
A4: 01.3 | B4: 01 | C4: Budget setup (corporate & project) | D4: Project (life-of-project) budget | E4: Project approved on feasibility, or new phase launched | F4: Project; phase; cost code; categories (land, planning, permits, titling, construction by milestone, marketing, sales, loan interest); contingency %; revenue forecast (units × price) | G4: Project Development → Budget on project analytic → Project WBS; baseline snapshot kept for variance | H4: Budgets spanning several fiscal years; re-baseline after scope change; price escalation; overrun beyond contingency | I4: Configure | J4: Finance – budget & FP&A
A5: 02.1 | B5: 02 | C5: Corporate & project financing | D5: Loan drawdown & allocation | E5: Loan agreement signed; approved funding requirement | F5: Lender; facility; principal; fixed/floating rate; tenor; drawdown date; amortization schedule; collateral; project allocation; capitalize-interest flag | G5: Treasury → Accounting (loan liability, interest accrual) → project analytic (capitalized interest) → AP (debt-service schedule) | H5: Repricing; prepayment penalties; stop capitalizing interest at completion; covenant breach | I5: Configure | J5: Treasury
A6: 03.1 | B6: 03 | C6: Corporate expenses | D6: Corporate expense request | E6: Department need arises | F6: Requester; cost center; category (branding, admin, departmental, executive); amount; budget line; vendor; attachments | G6: Purchase request / Approvals → budget check → PO → vendor bill (16) | H6: Unbudgeted urgent spend; recurring contracts (utilities, subscriptions); petty cash and reimbursements via Expenses | I6: Standard | J6: Administration / requesting departments
A7: 04.1 | B7: 04 | C7: Land acquisition | D7: Land due diligence | E7: Land opportunity logged | F7: Owner(s); location; OCT/TCT no.; lot area; tax declaration no.; zoning; encumbrances; appraised value; asking price; broker | G7: Custom land register + Documents workspace → Approvals to ManCom | H7: Title defects or adverse claims; multiple heirs (extrajudicial settlement); CARP/DAR coverage; informal settlers | I7: Extend | J7: Land acquisition / business development
A8: 04.2 | B8: 04 | C8: Land acquisition | D8: Land agreement & milestone payments | E8: ManCom approval | F8: Agreement type (deed of sale, CTS, JV); price; milestones (condition, date, %); taxes borne by; JV sharing ratio | G8: Sign → vendor bill per milestone → AP (16) → Accounting (land held for development / advances) | H8: JV landowner paid in units (non-cash, inventory allocation); unmet milestone conditions; renegotiation; installment interest | I8: Extend | J8: Land acquisition / business development
A9: 04.3 | B9: 04 | C9: Land acquisition | D9: Titling with fees | E9: Final payment made; deed notarized | F9: CGT; DST; transfer tax; registration fees; eCAR no.; new TCT no.; dates | G9: Fees → AP; TCT no. → land register and project master; land cost capitalized to project analytic | H9: Who shoulders taxes; late-filing surcharges; consolidation or subdivision of titles before development | I9: Extend | J9: Land acquisition / business development
A10: 05.1 | B10: 05 | C10: Project setup & project financing | D10: Project setup | E10: Land titled and project budget approved | F10: Project code; name; company; location; type (horizontal / vertical); phases; blocks or towers; WBS; analytic account; permits (DP, ECC, BP, CR/LTS) | G10: Project ↔ analytic account ↔ Budget; permit tracker; releases to unit creation (07.1) | H10: Project across entities or JV; phasing changes; no LTS means no selling — system must block reservations | I10: Configure | J10: Project Development
A11: 06.1 | B11: 06 | C11: Project expenses & construction (milestone-based) | D11: Construction contract & progress billing | E11: Contract awarded; accomplishment report submitted | F11: Contractor; contract amount; BOQ / cost code; downpayment %; retention %; progress %; cumulative billed; recoupment; variation orders; EWT | G11: Purchase (contract/PO) → Project milestone % → vendor bill with retention and recoupment → AP; % completion → unit construction status and POC revenue | H11: Variation orders; liquidated damages; back-charges; retention release after defects liability period; owner-furnished materials | I11: Extend | J11: Construction / cost control
A12: 07.1 | B12: 07 | C12: Inventory & financing options setup | D12: Lot master creation & pricing | E12: Project released for sale (LTS issued) | F12: Lot ID (project-phase-block-lot; tower-floor-unit for condos); house model; lot and floor area; list price / TCP; price per sqm; VAT treatment; parking; construction status; sales status; mother / derivative title | G12: Lot master (vendor-proposed) ↔ product and pricelist ↔ project analytic; availability board to CRM and brokers; every downstream document (reservation, CTS, ledger, turnover, title) references the Lot | H12: Condo units, parking slots and house-and-lot packages modeled as lots; lot merge or split; price increases on unsold lots only; management / model-unit holds; VAT threshold treatment | I12: Extend | J12: Sales admin / Project Development
A13: 07.2 | B13: 07 | C13: Inventory & financing options setup | D13: Financing options setup | E13: New price list or promo scheme | F13: Scheme (spot cash, deferred cash, bank, Pag-IBIG, IHF); reservation fee; DP % and months; discount %; interest rate; loanable %; term; validity | G13: Payment-term templates → sales computation (09.1) → amortization engine (11) | H13: Promo expiry; scheme change after reservation (restructuring); Pag-IBIG loan ceilings | I13: Extend | J13: Sales admin / Project Development
... A35: X2.1 | B35: X2 | C35: KPIs & variance reports | D35: KPIs & variance reporting | E35: Period close | F35: Budget vs actual by analytic account; absorption and sales velocity; collection efficiency; aging / DSO; % completion; cost variance | G35: Accounting budget report → dashboards / BI | H35: Timing differences (commitments vs actuals); reclassifications after close | I35: Configure | J35: Finance – FP&A

Sheet Master Data
A1: Object | B1: Owning process | C1: Key fields | D1: Indicative Odoo home | E1: Used by processes
A2: Company / entity | B2: 01 | C2: Legal name, TIN, BIR registration, CAS permit, fiscal year | D2: res.company | E2: All
A3: Analytic plans | B3: 01 | C3: Business unit, project, phase, cost center, expense type | D3: Accounting › Analytic plans | E3: 01, 03, 06, 16, X2
A4: Budget line | B4: 01 | C4: Version, account, analytic, period, amount, status | D4: Accounting › Budgets | E4: 03, 06, 14, 16, X2
A5: Land parcel | B5: 04 | C5: OCT/TCT, area, owner, cost, status, linked project | D5: Custom land register | E5: 04, 05, 19
A6: Project / phase | B6: 05 | C6: Code, type, phases, blocks/towers, WBS, permits, LTS | D6: project.project + analytic account | E6: 06, 07, 09, X1
A7: Lot (unit master) | B7: 07 | C7: Lot ID, project / phase / block, house model, lot and floor area, price, construction status, sales status, title no., current buyer / CTS | D7: Lot master model (vendor-proposed), linked to product.product and project analytic | E7: 09–15, 18, 19
A8: Payment scheme | B8: 07 | C8: Scheme type, RF, DP %/months, rate, term, validity | D8: Payment terms + custom scheme | E8: 09, 11, 13
A9: Buyer / co-borrower | B9: 09 | C9: Name, TIN, IDs, civil status, address, employer, SPA | D9: res.partner | E9: 09–15, 18, 19
A10: Broker / agent | B10: 08 | C10: PRC license, DHSUD reg., TIN, tier, validity, parent firm | D10: res.partner (tagged) | E10: 09, 17
A11: Contract to sell | B11: 09 | C11: CTS no., unit, TCP, schedule, clauses, signatures | D11: sale.order + sign.request | E11: 11, 12, 13, 17
A12: Buyer ledger / schedule | B12: 11 | C12: Due lines, allocations, penalties, balance | D12: account.move / account.payment + custom schedule | E12: 11, 12, 13, X1
... A15: Service ticket | B15: 18 | C15: Unit, category, SLA, warranty flag, cost | D15: helpdesk.ticket | E15: 15, 18

Sheet Lot Touchpoints
A1: Process | B1: What it does to the Lot (vendor-proposed master model) | C1: Fields needed on Lot | D1: Vendor response
A2: 04 Land acquisition · 05 Project setup | B2: Mother title and project / phase / block give the Lot its parent references
A3: 06 Construction | B3: Updates construction status and % completion
A4: 07 Inventory | B4: Creates the Lot, prices it, sets sales status to available
A5: 09 Sales · 12 Cancellations | B5: Reserved → sold; cancelled → available again (return inventory)
A6: 11 Accounts monitoring · 13 Takeout | B6: Buyer ledger, schedule and loan status hang off the Lot's active CTS
A7: 15 Turnover · 18 Property management | B7: Turned-over flag, warranty dates, homeowner and dues
A8: 19 Title delivery | B8: Derivative title number, custody and release

Sheet Open Items
A1: # | B1: Item | C1: Owner | D1: Decision | E1: Target date | F1: Status
A2: Q1 | B2: TORC scope. TORC = taxes and other related charges. List each tax and charge PHI books under it, who shoulders each (buyer vs developer), and whether it is advanced and recharged or billed upfront. | F2: Open
A3: Q2 | B3: Process numbering. Confirm the proposed numbers for 01–03, 05–13 and 17 so every BRD chapter uses one ID set. | F3: Open
A4: Q3 | B4: Turnover eligibility. Which payment status allows turnover (equity paid, loan approved, fully paid) and who can approve exceptions? | F4: Open
A5: Q4 | B5: Revenue recognition. Agree the PFRS 15 method, collectability threshold and POC source with the external auditor before the Accounting design. | F5: Open
A6: Q5 | B6: Commission release rules. Tranches, clawback on cancellation, and treatment of in-house vs external brokers. | F6: Open
A7: Q6 | B7: Invoicing compliance. Current BIR CAS permit status and e-invoicing timeline — decides whether Odoo prints the official invoice series from go-live. | F7: Open
A8: Q7 | B8: Lot as master model (vendor proposal). Confirm whether "Lot" is a custom real-estate model or Odoo's serial/lot record (stock.lot), and how it represents condo units, parking slots, house-and-lot packages, and merged or split lots. | F8: Open
A9: Q8 | B9: Lot status design. Separate construction status and sales status fields on the Lot, and who may change each (Construction, Sales admin, Credit & collection, Titling). | F9: Open
A10: Q9 | B10: Migration from In4 Velocity. How much buyer-ledger history moves (open balances only, or full payment history needed for Maceda computations)? | F10: Open
A11: Q10 | B11: Approval matrix (DOA). Amount thresholds per document type, per company and per project to configure in Approvals. | F11: Open

Sheet SOW Gap Analysis
A1: Gap analysis — blueprint (SIPOC + data matrix) vs vendor SOW
A2: Rating: Covered = SOW clearly delivers it · Partial = some of it, gaps listed · Not covered = absent. Yellow columns are for PHI and vendor responses.
A4: Summary
A5: Covered | B5: =COUNTIF($D$12:$D$32,A5) -> 8
A6: Partial | B6: =COUNTIF($D$12:$D$32,A6) -> 12
A7: Not covered | B7: =COUNTIF($D$12:$D$32,A7) -> 1
A8: High-priority gaps (processes) | B8: =COUNTIFS($G$12:$G$32,"High",$D$12:$D$32,"<>Covered") -> 8
A9: Processes assessed | B9: =COUNTA($A$12:$A$32) -> 21
A10: Deferred to next phase | B10: =COUNTIF($N$12:$N$32,"Deferred*") -> 2
A11: Proc ID | B11: Process | C11: Blueprint requirement | D11: Coverage rating | E11: SOW coverage (section / item) | F11: Gaps and missing scope | G11: Priority | H11: Recommended action | I11: Matrix steps affected | J11: SOW items mapped | K11: Dev-days touching process* | L11: PHI owner response | M11: Vendor response | N11: Status
A12: 01 | B12: Budget setup (corporate & project) | C12: Corporate + life-of-project budgets by phase and cost code; budget cycle (prepare → consolidate → ManCom approval → lock); budget check on PR/PO/bill; realignment | D12: Partial | E12: §3.1 G Finance Core (corporate & department budget, burn-rate; TORC budget rule builder; project P&L; budget vs actual) | F12: No budget preparation / consolidation / approval workflow or versioning; no multi-year project budget or re-baseline; budget check at PR/PO stage not stated (only TORC dispensing). | G12: High | H12: Clarify in BRD: budget cycle workflow, versions, PR/PO budget check. Price as CR if not in base. | I12: 01.1, 01.2, 01.3 | J12: =COUNTIF('SOW Scope Map'!$E$5:$E$104,"*"&A12&"*") -> 0 | K12: =SUMIF('SOW Scope Map'!$E$5:$E$104,"*"&A12&"*",'SOW Scope Map'!$D$5:$D$104) -> 0 | N12: Open
A13: 02 | B13: Corporate & project financing | C13: Loan drawdown, allocation to projects, interest accrual and capitalization, debt service | D13: Partial | E13: §3.3 #99–100 Company Loans (payment processing, schedule view, cash-flow forecast link) | F13: Debt service covered. Drawdown allocation per project, interest capitalization to project cost (and stop at completion), covenant tracking not mentioned. | G13: Medium | H13: Add allocation + capitalized-interest rules to BRD; confirm with Finance. | I13: 02.1 | J13: =COUNTIF('SOW Scope Map'!$E$5:$E$104,"*"&A13&"*") -> 2 | K13: =SUMIF('SOW Scope Map'!$E$5:$E$104,"*"&A13&"*",'SOW Scope Map'!$D$5:$D$104) -> 12.96 | N13: Open
A14: 03 | B14: Corporate expenses | C14: Request → budget check → PO/contract → receipt → bill → AP for corporate spend | D14: Covered | E14: §3.1 F Non-project payments (same approval & posting pipeline); §3.2 Purchase, Accounting | F14: Petty cash / reimbursements (Odoo Expenses) not mentioned. | G14: Low | H14: Confirm Expenses app is in scope or handled manually. | I14: 03.1 | J14: =COUNTIF('SOW Scope Map'!$E$5:$E$104,"*"&A14&"*") -> 0 | K14: =SUMIF('SOW Scope Map'!$E$5:$E$104,"*"&A14&"*",'SOW Scope Map'!$D$5:$D$104) -> 0 | N14: Open
A15: 04 | B15: Land acquisition | C15: Due diligence, agreements, milestone payments, taxes and title transfer, land bank | D15: Covered | E15: §3.1 C Land Acquisition; D Land banking register & carrying costs; §3.3 #1–4, 12, 16–26, 29–30, 56–63, 86–87 | F15: Strong coverage (multi-owner, DOAS, BIR/LGU filing tracker, land bank). JV with landowner paid in units (non-cash allocation) not mentioned; CARP/heirs flags depend on DD checklist content. | G15: Medium | H15: Confirm JV / land-for-units treatment in Discovery. | I15: 04.1, 04.2, 04.3 | J15: =COUNTIF('SOW Scope Map'!$E$5:$E$104,"*"&A15&"*") -> 30 | K15: =SUMIF('SOW Scope Map'!$E$5:$E$104,"*"&A15&"*",'SOW Scope Map'!$D$5:$D$104) -> 171.36 | N15: Open
A16: 05 | B16: Project setup & project financing | C16: Project master, phases/WBS, analytic account, permits (DP, ECC, BP, CR/LTS); block selling without LTS | D16: Partial | E16: §3.1 C Project Setup Wizard, launch readiness gate; D Land bank → project conversion; §3.3 #6–15, 37, 62, 70 | F16: No explicit permit / License to Sell tracker; 5-criteria launch gate is land-oriented (title, payments, construction) — LTS not listed as a criterion. Wizard Step 1 (Info) is in §3.1 but not itemized in §3.3. | G16: High | H16: Add LTS / DHSUD permits as a launch-gate criterion and permit register. Ask why Step 1 is unpriced. | I16: 05.1 | J16: =COUNTIF('SOW Scope Map'!$E$5:$E$104,"*"&A16&"*") -> 15 | K16: =SUMIF('SOW Scope Map'!$E$5:$E$104,"*"&A16&"*",'SOW Scope Map'!$D$5:$D$104) -> 77.76 | N16: Open
A17: 06 | B17: Project expenses & construction (milestone-based) | C17: Contract award, progress billing with retention and DP recoupment, variation orders, % completion, POC link | D17: Partial | E17: §3.1 B Subcontractor billing workflow; F Contracts & deliverables (milestones, retention); D construction schedule, cost ledger; §3.3 #66–69 | F17: Retention and milestone release covered. DP recoupment, variation orders, liquidated damages, back-charges not mentioned. BOQ listed in §3.2 but no build item. % completion does not feed revenue recognition (see C1). | G17: High | H17: Walk vendor through 06.1 exceptions; get written coverage or CR price. | I17: 06.1 | J17: =COUNTIF('SOW Scope Map'!$E$5:$E$104,"*"&A17&"*") -> 6 | K17: =SUMIF('SOW Scope Map'!$E$5:$E$104,"*"&A17&"*",'SOW Scope Map'!$D$5:$D$104) -> 31.68 | N17: Open
A18: 07 | B18: Inventory & financing options setup | C18: Lot as unit master, pricing and escalation, construction + sales status, financing schemes and payment terms | D18: Covered | E18: §3.1 D Inventory (Lot master, pricing floor, governed status workflow); H pricing rules engine; §3.3 #5, 16, 27–28, 69, 73 | F18: Lot model (lam.lot) is built around block/lot land parcels. Condo units (tower-floor-unit), parking slots and house-and-lot packages not addressed. Pag-IBIG not listed among pricing schemes in H (only in Customer Loans). | G18: High | H18: Confirm the Lot model handles vertical projects before sign-off. | I18: 07.1, 07.2 | J18: =COUNTIF('SOW Scope Map'!$E$5:$E$104,"*"&A18&"*") -> 7 | K18: =SUMIF('SOW Scope Map'!$E$5:$E$104,"*"&A18&"*",'SOW Scope Map'!$D$5:$D$104) -> 36 | N18: Open
A19: 08 | B19: Sales channel accreditation | C19: Broker/agent accreditation, PRC/DHSUD/TIN docs, validity, commission scheme | D19: Covered | E19: §3.1 E Partner & accreditation; §3.3 #40, 48–49, 55, 64 | F19: Expiry alerts included. Agent moving firms mid-deal not explicit. | G19: Low | H19: Confirm in BRD. | I19: 08.1 | J19: =COUNTIF('SOW Scope Map'!$E$5:$E$104,"*"&A19&"*") -> 5 | K19: =SUMIF('SOW Scope Map'!$E$5:$E$104,"*"&A19&"*",'SOW Scope Map'!$D$5:$D$104) -> 24.48 | N19: Open
A20: 09 | B20: Sales (reservation to contract to sell) | C20: Sales computation, reservation, document & credit check, CTS generation and notarization, payment schedule, revenue recognition | D20: Partial | E20: §3.1 H Reservation; E Sales; A buyer docs (OCR); §3.3 #31–39, 50–52, 54 | F20: Reservation → SO flow is strong. No Contract to Sell (CTS) document template, signing and notarization tracking — the SO stands in for the contract. No credit-evaluation step. Discount approval implied, not explicit. | G20: High | H20: Add CTS generation (template, e-sign/notarization status) and credit check to scope. | I20: 09.1, 09.2, 09.3 | J20: =COUNTIF('SOW Scope Map'!$E$5:$E$104,"*"&A20&"*") -> 15 | K20: =SUMIF('SOW Scope Map'!$E$5:$E$104,"*"&A20&"*",'SOW Scope Map'!$D$5:$D$104) -> 92.16 | N20: Open
A21: 10 | B21: Leasing | C21: Lease term sheet, contract, recurring rent/CUSA billing, deposits, renewals | D21: Not covered | E21: None | F21: Leasing is absent from the SOW. | G21: Medium | H21: Deferred to a later phase by PHI decision. Not included in the vendor clarification letter; no pricing requested. | I21: 10.1 | J21: =COUNTIF('SOW Scope Map'!$E$5:$E$104,"*"&A21&"*") -> 0 | K21: =SUMIF('SOW Scope Map'!$E$5:$E$104,"*"&A21&"*",'SOW Scope Map'!$D$5:$D$104) -> 0 | N21: Deferred (next phase)
A22: 11 | B22: Accounts monitoring (documentation, receipting, collection) | C22: Buyer documents, BIR-compliant receipting, collection posting and allocation, SOA, penalties, aging, demand letters | D22: Partial | E22: §3.1 I Customer Loans (allocation, statements, aging); J Customer Servicing (SOA); §3.3 #34, 39, 74–77, 95, 97–98 | F22: Allocation (penalty → interest → principal), SOA, grace period and aging covered. PDC warehousing and bounced checks, demand-letter generation and BIR-registered invoice/receipt series not mentioned. | G22: High | H22: Add PDC management and demand letters; confirm BIR invoice series (see C2). | I22: 11.1, 11.2, 11.3 | J22: =COUNTIF('SOW Scope Map'!$E$5:$E$104,"*"&A22&"*") -> 15 | K22: =SUMIF('SOW Scope Map'!$E$5:$E$104,"*"&A22&"*",'SOW Scope Map'!$D$5:$D$104) -> 86.4 | N22: Open
A23: 12 | B23: Cancellations & return to inventory | C23: Maceda-compliant cancellation: grace, notarial notice, cash surrender value, refund/forfeiture, reversals, return to inventory | D23: Partial | E23: §3.3 #36 (SO cancel releases lot), #43 (commission clawback), H reservation cancel/release | F23: Only the inventory release and commission clawback are covered. No RA 6552 cash-surrender-value computation, notice tracking, refund processing, forfeiture income or AR/revenue reversal. | G23: High | H23: Add a cancellation workflow with Maceda calculator as base scope, not CR — it is a statutory requirement. | I23: 12.1 | J23: =COUNTIF('SOW Scope Map'!$E$5:$E$104,"*"&A23&"*") -> 1 | K23: =SUMIF('SOW Scope Map'!$E$5:$E$104,"*"&A23&"*",'SOW Scope Map'!$D$5:$D$104) -> 7.2 | N23: Open
... A32: X2 | B32: KPIs & variance reports | C32: Budget vs actual and KPI reporting across processes | D32: Covered | E32: §3.1 G Finance BI; many dashboards (§3.3 #1–6, 86–91) | F32: Well covered. | G32: Low | H32: None. | I32: X2.1 | J32: =COUNTIF('SOW Scope Map'!$E$5:$E$104,"*"&A32&"*") -> 7 | K32: =SUMIF('SOW Scope Map'!$E$5:$E$104,"*"&A32&"*",'SOW Scope Map'!$D$5:$D$104) -> 38.88 | N32: Open
A33: * Items that touch several processes are counted in each, so this column does not sum to the SOW total.
A35: Cross-cutting gaps
A36: Ref | B36: Topic | C36: SOW reference | D36: Coverage rating | E36: Gap | F36: Recommended action | G36: Priority | H36: PHI owner response | I36: Vendor response | J36: Status
A37: C1 | B37: Revenue recognition (PFRS 15, over-time / % of completion) | C37: Not in SOW | D37: Not covered | E37: No mention of revenue recognition, POC journals or significant financing component — central to a developer's financials. | F37: Add to Finance Core; agree method with external auditor first. | G37: High | J37: Open
A38: C2 | B38: BIR compliance detail | C38: Objectives mention EWT and BIR; §9 excludes non-PH filings | D38: Partial | E38: CAS permit / registered invoice series, EOPT invoicing rules, e-invoicing (EIS), 2307, SAWT, QAP, alphalist and VAT on real property thresholds are not itemized. | F38: Get a written list of PH statutory outputs delivered. | G38: High | J38: Open
A39: C3 | B39: Data migration from In4 Velocity | C39: §3.4 data migration; §7 CSV Rule; §9 excludes history beyond cut-off | D39: Partial | E39: Only templated master data and opening balances. Maceda computations need full payment history (years paid); commission and takeout status also need history. | F39: Agree cut-off and which buyer-ledger history migrates; size it now, not as flex. | G39: High | J39: Open
A40: C4 | B40: Vertical / condo projects in the Lot model | C40: §3.1 D, §8 (existing Lot model 'stable and documented') | D40: Partial | E40: Lot model is land-lot based (block/lot, TCT). CCT titles, tower-floor-unit, parking not addressed. | F40: Confirm project mix and model design. | G40: High | J40: Open
A41: C5 | B41: Existing internal systems | C41: §9 limits integrations to CSV/MT940 imports | D41: Not covered | E41: No data feed to PHI's existing internal systems (e.g., BI dashboards, SharePoint document stores). | F41: List systems that must read Odoo data; decide API vs export. | G41: Medium | J41: Open
A42: C6 | B42: Mockups referenced but not attached | C42: §3.3 'based on the Mockups' | D42: Partial | E42: Scope items are defined by mockups that are not part of the SOW; items #62–64 have no description at all. | F42: Attach mockups as an SOW annex; describe #62–64. | G42: Medium | J42: Open
A44: In the SOW but not yet in the blueprint (update the blueprint)
A45: # | B45: SOW capability | C45: Blueprint process(es) | D45: Suggested blueprint update
A46: S1 | B46: Buyer self-service portal (SOA, payments, documents, concerns, turnover status) | C46: 11, 15, 19 | D46: Add portal as a channel in SIPOC for 11 and 15
A47: S2 | B47: Broker / agent portal (listings, lead registration, reservation requests, commission view) | C47: 08, 09, 17 | D47: Add as a channel in 08 and 09
A48: S3 | B48: Supplier accreditation workflow and performance rating | C48: 03, 06, 16 | D48: Add supplier accreditation as a step in procure-to-pay
A49: S4 | B49: Land banking register, carrying cost ledger and conversion to project | C49: 04, 05 | D49: Add land bank to 04 outputs and 05 inputs
A50: S5 | B50: 5-criteria launch readiness gate and internal land → sales turnover | C50: 05, 07 | D50: Add gate to diagram B before lot creation
A51: S6 | B51: Helpdesk with SLA, CSAT and construction punch-list | C51: 15, 18 | D51: Add CSAT and SLA to 15 / 18 outputs
...

Sheet SOW Scope Map
A1: SOW §3.3 customizations mapped to blueprint processes
A2: Source: Achieve Without Borders SOW S343096 (Odoo v19), dated 24 Sep 2026. Dev man-days transcribed as stated in the SOW.
A4: # | B4: Section | C4: Feature | D4: Dev man-days | E4: Blueprint process(es) | F4: Process name(s)
A5: 1 | B5: Dashboard | C5: Acquisition KPI Cards | D5: 4.32 | E5: 04 | F5: Land acquisition
A6: 2 | B6: Dashboard | C6: Attention Required List | D6: 5.76 | E6: 04 | F6: Land acquisition
A7: 3 | B7: Dashboard | C7: Project Progress Bars | D7: 2.88 | E7: 04 | F7: Land acquisition
A8: 4 | B8: Dashboard | C8: Quick Navigation | D8: 2.88 | E8: 04 | F8: Land acquisition
A9: 5 | B9: Dashboard | C9: Lot Inventory | D9: 5.76 | E9: 07 | F9: Inventory & financing options setup
A10: 6 | B10: Dashboard | C10: Project | D10: 4.32 | E10: 05 | F10: Project setup & project financing
A11: 7 | B11: Projects & Pipeline | C11: Project Consolidated View | D11: 5.76 | E11: 04, 05 | F11: Land acquisition; Project setup & project financing
A12: 8 | B12: Projects & Pipeline | C12: Project Search & Filters | D12: 4.32 | E12: 05 | F12: Project setup & project financing
A13: 9 | B13: Project Setup Wizard | C13: Step 2 - Site Details | D13: 4.32 | E13: 05 | F13: Project setup & project financing
A14: 10 | B14: Project Setup Wizard | C14: Step 3 - Targets | D14: 4.32 | E14: 05 | F14: Project setup & project financing
A15: 11 | B15: Project Setup Wizard | C15: Step 4 - Team Assignment | D15: 4.32 | E15: 05 | F15: Project setup & project financing
A16: 12 | B16: Project Setup Wizard | C16: Step 5 - Milestone Template | D16: 5.76 | E16: 04 | F16: Land acquisition
... A104: 100 | B104: Company Loans | C104: Company Loan Schedule List View | D104: 4.32 | E104: 02, X1 | F104: Corporate & project financing; Forecasts
A106: Total itemized dev man-days | D106: =SUM(D5:D104) -> 573.12
A108: Section subtotal check
B109: Section | C109: SOW stated subtotal | D109: Computed from items | E109: Difference
B110: Dashboard | C110: 25.92 | D110: =SUMIF($B$5:$B$104,B110,$D$5:$D$104) -> 25.92 | E110: =ROUND(D110-C110,2) -> 0
B111: Projects & Pipeline | C111: 10.08 | D111: =SUMIF($B$5:$B$104,B111,$D$5:$D$104) -> 10.08 | E111: =ROUND(D111-C111,2) -> 0
B112: Project Setup Wizard | C112: 31.68 | D112: =SUMIF($B$5:$B$104,B112,$D$5:$D$104) -> 31.68 | E112: =ROUND(D112-C112,2) -> 0
B113: Lot Onboarding Form | C113: 38.88 | D113: =SUMIF($B$5:$B$104,B113,$D$5:$D$104) -> 38.88 | E113: =ROUND(D113-C113,2) -> 0
B114: Acquisition & Payments (Multi-Owner) | C114: 33.12 | D114: =SUMIF($B$5:$B$104,B114,$D$5:$D$104) -> 33.12 | E114: =ROUND(D114-C114,2) -> 0
B115: Lot Detail & Lifecycle | C115: 21.6 | D115: =SUMIF($B$5:$B$104,B115,$D$5:$D$104) -> 21.6 | E115: =ROUND(D115-C115,2) -> 0
B116: CRM → Reservation → Sales Order | C116: 63.36 | D116: =SUMIF($B$5:$B$104,B116,$D$5:$D$104) -> 63.36 | E116: =ROUND(D116-C116,2) -> 0
B117: Broker Commission | C117: 54.72 | D117: =SUMIF($B$5:$B$104,B117,$D$5:$D$104) -> 54.72 | E117: =ROUND(D117-C117,2) -> 0
B118: Broker Portal | C118: 41.76 | D118: =SUMIF($B$5:$B$104,B118,$D$5:$D$104) -> 41.76 | E118: =ROUND(D118-C118,2) -> 0
B119: Payment Milestones & Reminders | C119: 23.04 | D119: =SUMIF($B$5:$B$104,B119,$D$5:$D$104) -> 23.04 | E119: =ROUND(D119-C119,2) -> 0
B120: Approvals & Documents | C120: 33.12 | D120: =SUMIF($B$5:$B$104,B120,$D$5:$D$104) -> 33.12 | E120: =ROUND(D120-C120,2) -> 0
B121: Construction Monitoring | C121: 21.6 | D121: =SUMIF($B$5:$B$104,B121,$D$5:$D$104) -> 21.6 | E121: =ROUND(D121-C121,2) -> 0
... B128: Company Loans | C128: 12.96 | D128: =SUMIF($B$5:$B$104,B128,$D$5:$D$104) -> 12.96 | E128: =ROUND(D128-C128,2) -> 0
B129: Total | C129: =SUM(C110:C128) -> 573.12 | D129: =SUM(D110:D128) -> 573.12 | E129: =ROUND(D129-C129,2) -> 0
B130: Blue = figures typed from the SOW. Differences of 0.00 mean the SOW section subtotals add up.

Sheet SOW Effort Check
A1: SOW §5.1 effort table — arithmetic and capacity check
A2: Figures typed from §5.1 in blue. As printed, the Dev Lead column carries more days than Developer; ask the vendor to confirm.
A4: Workstream | B4: Lead Functional Consultant | C4: BA | D4: Dev Lead | E4: Developer | F4: QA | G4: Infra | H4: SOW stated total | I4: Computed total | J4: Difference
A5: CRM, Buyer & Agent Portal | B5: 10 | C5: 7 | D5: 29 | E5: 10 | H5: 56 | I5: =SUM(B5:G5) -> 56 | J5: =I5-H5 -> 0
A6: Construction Monitoring | B6: 6 | C6: 5 | D6: 19 | E6: 6 | H6: 36 | I6: =SUM(B6:G6) -> 36 | J6: =I6-H6 -> 0
A7: Land Acquisition | B7: 10 | C7: 7 | D7: 31 | E7: 10 | H7: 58 | I7: =SUM(B7:G7) -> 58 | J7: =I7-H7 -> 0
A8: Inventory Management | B8: 10 | C8: 7 | D8: 31 | E8: 10 | H8: 58 | I8: =SUM(B8:G8) -> 58 | J8: =I8-H8 -> 0
A9: Sales Management & Commissions | B9: 10 | C9: 7 | D9: 29 | E9: 10 | H9: 56 | I9: =SUM(B9:G9) -> 56 | J9: =I9-H9 -> 0
A10: Supplier & Payments | B10: 8 | C10: 6 | D10: 27 | E10: 8 | H10: 49 | I10: =SUM(B10:G10) -> 49 | J10: =I10-H10 -> 0
A11: Finance Core & TORC Budget | B11: 10 | C11: 7 | D11: 26 | E11: 10 | H11: 53 | I11: =SUM(B11:G11) -> 53 | J11: =I11-H11 -> 0
A12: Reservation Management | B12: 7 | C12: 6 | D12: 22 | E12: 7 | H12: 42 | I12: =SUM(B12:G12) -> 42 | J12: =I12-H12 -> 0
A13: Customer Loans & Financing | B13: 7 | C13: 12 | D13: 37 | E13: 10 | F13: 7 | H13: 72 | I13: =SUM(B13:G13) -> 73 | J13: =I13-H13 -> 1
A14: Customer Servicing Portal | B14: 6 | C14: 5 | D14: 17 | E14: 6 | H14: 34 | I14: =SUM(B14:G14) -> 34 | J14: =I14-H14 -> 0
A15: Data Migration, UAT & Training | B15: 12 | C15: 5 | D15: 14 | E15: 14 | F15: 10 | H15: 55 | I15: =SUM(B15:G15) -> 55 | J15: =I15-H15 -> 0
A16: Infrastructure, Environments & Cutover | D16: 3 | G16: 29 | H16: 32 | I16: =SUM(B16:G16) -> 32 | J16: =I16-H16 -> 0
A17: Project Management & Governance | B17: 48 | H17: 48 | I17: =SUM(B17:G17) -> 48 | J17: =I17-H17 -> 0
A18: Hypercare (90 days post go-live) | H18: 90 | I18: =H18 -> 90 | J18: n/a (not split by role)
A19: Total | B19: =SUM(B5:B18) -> 144 | C19: =SUM(C5:C18) -> 74 | D19: =SUM(D5:D18) -> 285 | E19: =SUM(E5:E18) -> 101 | F19: =SUM(F5:F18) -> 17 | G19: =SUM(G5:G18) -> 29 | H19: =SUM(H5:H18) -> 739 | I19: =SUM(I5:I18) -> 740 | J19: =I19-H19 -> 1
A21: Capacity vs itemized build
A22: Development capacity in §5.1 (Dev Lead + Developer) | B22: =D19+E19 -> 386
A23: Itemized §3.3 customization dev man-days | B23: ='SOW Scope Map'!D106 -> 573.12
A24: Shortfall (itemized minus capacity) | B24: =B23-B22 -> 187.12
A25: Shortfall as % of itemized | B25: =IF(B23=0,0,B24/B23) -> 0.32649358
A26: §3.1 lists further features that have no §3.3 line (land banking, supplier module, TORC budget, project P&L), so the real gap is larger than shown.

Sheet SOW Observations
A1: Commercial and contract observations on the SOW
A2: For discussion with the vendor and PHI Legal before signature. Not legal advice.
A4: # | B4: Observation | C4: SOW reference | D4: Finding | E4: Impact on PHI | F4: Suggested ask | G4: Owner | H4: Status
A5: O1 | B5: Build effort vs itemized scope | C5: §3.3 vs §5.1 | D5: The 100 itemized customizations total 573.12 dev-days. The two development columns in §5.1 (Dev Lead + Developer) total only 386 person-days, and §3.1 adds features not in §3.3 (land banking, supplier module, TORC budget, project P&L). | E5: Scope looks under-resourced by roughly a third; risk of rushed build or later change orders. | F5: Ask the vendor to reconcile, and confirm in writing that every §3.1 and §3.3 item is inside the Fixed Base Fee. | H5: Open
A6: O2 | B6: §5.1 columns look swapped | C6: §5.1 | D6: As printed, Dev Lead carries 285 days and Developer 101 — the reverse of what a normal team shape would be. | E6: Unclear team composition. | F6: Ask for the corrected table and named roles. | H6: Open
A7: O3 | B7: Arithmetic error: Customer Loans row | C7: §5.1 | D7: 7 + 12 + 37 + 10 + 7 = 73, but the row total says 72. The grand total of 739 uses 72. | E7: Minor, but signals the table wasn't checked. | F7: Ask for a corrected table. | H7: Open
A8: O4 | B8: Payment gateway: in scope and out of scope | C8: §3.3 #76 vs §9 | D8: Item #76 (8.64 dev-days) builds online payment via gateway, while §9 lists payment gateway integration as out of scope. | E8: PHI may pay for #76 and again for a CR. | F8: Resolve: either remove #76's gateway part from the fee or remove it from §9. | H8: Open
A9: O5 | B9: Two man-day rates | C9: Cover page vs §10.2 | D9: Base effort priced at PHP 10,000/day (739 × 10,000 = 7.39M); flex, overages and replenishments at PHP 12,000/day. | E9: Gaps found in this analysis would be priced at the higher rate. | F9: Negotiate the gap items into base scope before signing, or lock CRs at 10,000. | H9: Open
