Workbook

Sheet README
A1: PHI Process Re-engineering Opportunities
A3: Purpose | B3: Group CIO challenge to Primary Homes Incorporated: where PHI can process faster, see more clearly and report better — without weakening financial controls or compliance — before and through the Odoo 19 rollout.
A4: Basis | B4: PHI Enterprise Process Blueprint (SIPOC, BPMN swimlanes, data & interconnection matrix) and the vendor SOW S343096.
A5: How to read | B5: Each row of the Re-engineering Map shows, side by side: the current process (grey), the proposed re-engineered process (green), and the justification plus control safeguards (blue). The Before-After Detail sheet expands each opportunity: the full justification (problem, fix, control effect, expected outcome) and the step-by-step process before and after, with what changes and who is affected.
A6: Waves | B6: Wave 0 – Now (before BRD): policy and design decisions that shape what gets built. Wave 1 – Odoo build (2027 rollout): designed into the BRD and configured. Wave 2 – After go-live: optimisation once hypercare ends.
A7: Benefit tags | B7: Efficiency = less effort or cycle time. Transparency = status and accountability visible. Reporting = faster, consistent, trusted numbers.
A8: Control principle | B8: No proposal removes a control. Each moves the control earlier (prevent rather than detect), makes it system-enforced, or makes it evidenced. See the "Controls & compliance safeguards" column.
A9: Current process | B9: Taken from the blueprint and SOW. Items marked "to be validated" are assumptions PHI must confirm.
A10: Targets | B10: Proposed challenge targets. PHI should record a baseline first (KPI Scorecard sheet) and agree the final target with the process owner.
A11: Yellow cells | B11: PHI responses: decision, owner, target date, comments, baselines.
A12: Example input | B12: RE-10 → PHI decision "Accept with changes"; Comment "Start with new buyers from Q1 2027; keep PDCs for existing accounts"; Owner "Treasury head".
A13: Compliance references | B13: PD 957 (License to Sell), RA 6552 (Maceda Law), RA 10173 (Data Privacy Act), BIR requirements including EOPT invoicing and 2307, PFRS 15. Confirm applicability with PHI Legal, Tax and the external auditor.

Sheet Summary
A1: Summary
A2: Counts update automatically from the Re-engineering Map.
A4: By wave
A5: Wave where it starts | B5: Opportunities | C5: Efficiency | D5: Transparency | E5: Reporting | F5: Accepted by PHI
A6: Wave 0 – Now (before BRD) | B6: =COUNTIF('Re-engineering Map'!$J$5:$J$27,A6) -> 15 | C6: =COUNTIFS('Re-engineering Map'!$J$5:$J$27,$A6,'Re-engineering Map'!$I$5:$I$27,"*Efficiency*") -> 12 | D6: =COUNTIFS('Re-engineering Map'!$J$5:$J$27,$A6,'Re-engineering Map'!$I$5:$I$27,"*Transparency*") -> 14 | E6: =COUNTIFS('Re-engineering Map'!$J$5:$J$27,$A6,'Re-engineering Map'!$I$5:$I$27,"*Reporting*") -> 8 | F6: =COUNTIFS('Re-engineering Map'!$J$5:$J$27,$A6,'Re-engineering Map'!$P$5:$P$27,"Accept*") -> 0
A7: Wave 1 – Odoo build (2027 rollout) | B7: =COUNTIF('Re-engineering Map'!$J$5:$J$27,A7) -> 8 | C7: =COUNTIFS('Re-engineering Map'!$J$5:$J$27,$A7,'Re-engineering Map'!$I$5:$I$27,"*Efficiency*") -> 7 | D7: =COUNTIFS('Re-engineering Map'!$J$5:$J$27,$A7,'Re-engineering Map'!$I$5:$I$27,"*Transparency*") -> 6 | E7: =COUNTIFS('Re-engineering Map'!$J$5:$J$27,$A7,'Re-engineering Map'!$I$5:$I$27,"*Reporting*") -> 5 | F7: =COUNTIFS('Re-engineering Map'!$J$5:$J$27,$A7,'Re-engineering Map'!$P$5:$P$27,"Accept*") -> 0
A8: Wave 2 – After go-live | B8: =COUNTIF('Re-engineering Map'!$J$5:$J$27,A8) -> 0 | C8: =COUNTIFS('Re-engineering Map'!$J$5:$J$27,$A8,'Re-engineering Map'!$I$5:$I$27,"*Efficiency*") -> 0 | D8: =COUNTIFS('Re-engineering Map'!$J$5:$J$27,$A8,'Re-engineering Map'!$I$5:$I$27,"*Transparency*") -> 0 | E8: =COUNTIFS('Re-engineering Map'!$J$5:$J$27,$A8,'Re-engineering Map'!$I$5:$I$27,"*Reporting*") -> 0 | F8: =COUNTIFS('Re-engineering Map'!$J$5:$J$27,$A8,'Re-engineering Map'!$P$5:$P$27,"Accept*") -> 0
A9: Total | B9: =SUM(B6:B8) -> 23 | C9: =SUM(C6:C8) -> 19 | D9: =SUM(D6:D8) -> 20 | E9: =SUM(E6:E8) -> 13 | F9: =SUM(F6:F8) -> 0
A10: Continue into Wave 2 (optimise after go-live) | B10: =COUNTIF('Re-engineering Map'!$K$5:$K$27,"*2*") -> 3
A11: By SOW status
A12: SOW status | B12: Opportunities | C12: Meaning
A13: Covered | B13: =COUNTIF('Re-engineering Map'!$M$5:$M$27,"Covered*") -> 9 | C13: SOW already builds the enabler — PHI must adopt the new way of working
A14: Partial | B14: =COUNTIF('Re-engineering Map'!$M$5:$M$27,"Partial*") -> 8 | C14: Enabler partly in SOW — depends on Appendix A items being priced
A15: Gap | B15: =COUNTIF('Re-engineering Map'!$M$5:$M$27,"Gap*") -> 3 | C15: Enabler not in SOW — depends on Appendix A items
A16: Confirm | B16: =COUNTIF('Re-engineering Map'!$M$5:$M$27,"Confirm*") -> 1 | C16: Depends on a vendor confirmation (Appendix B)
A17: Policy | B17: =COUNTIF('Re-engineering Map'!$M$5:$M$27,"Policy*") -> 1 | C17: Policy or governance change only
A18: Client | B18: =COUNTIF('Re-engineering Map'!$M$5:$M$27,"Client*") -> 1 | C18: PHI obligation under the SOW
A19: Total | B19: =SUM(B13:B18) -> 23
A20: Check (should equal total opportunities) | B20: =B19-B9 -> 0
A22: Process change across all opportunities
A23: Process steps before | B23: ='Before-After Detail'!N28 -> 125
A24: Process steps after | B24: ='Before-After Detail'!O28 -> 133
A25: Manual, paper, re-key or wait steps before | B25: ='Before-After Detail'!P28 -> 120
A26: Automated or system-enforced steps after | B26: ='Before-After Detail'!Q28 -> 82
A27: Steps moved earlier or run in parallel | B27: ='Before-After Detail'!R28 -> 7
A28: Share of after-steps automated or system-enforced | B28: =IF(B24=0,0,B26/B24) -> 0.61654135

Sheet Re-engineering Map
A1: Re-engineering map — current vs proposed, with justification
A2: Grey = current process · Green = proposed · Blue = justification and control safeguards · Yellow = PHI response.
A4: ID | B4: Opportunity | C4: Blueprint process | D4: Current process | E4: Pain points and control risks | F4: Proposed re-engineered process | G4: Justification | H4: Controls & compliance safeguards | I4: Benefit | J4: Wave (start) | K4: Continues into | L4: Odoo 19 enabler | M4: SOW status | N4: KPI | O4: Proposed target | P4: PHI decision | Q4: PHI owner | R4: Target date | S4: PHI comments
A5: RE-01 | B5: Driver-based budget with commitment control | C5: 01 | D5: Annual static budget: departments and PDD fill templates, Finance consolidates, ManCom approves. Spending is checked against budget mainly when the bill arrives. | E5: Budget is outdated within months. Overspend is found after the commitment is made. Consolidation is heavy manual work. | F5: Build the budget from drivers (units, prices, cost per sqm, headcount) and reforecast quarterly. Check budget availability at purchase request and reserve the amount (commitment control). | G5: Overspend is caught before PHI is committed, not after the invoice. Reforecasting replaces most re-budgeting. Drivers make consolidation automatic and explainable. | H5: Approved baseline locked and versioned. Realignments above threshold need DOA approval. Every override logged. | I5: Efficiency, Transparency, Reporting | J5: Wave 0 – Now (before BRD) | K5: Wave 1 | L5: Budgets (analytic plans), Purchase approvals, Spreadsheet | M5: Gap — Appendix A8 | N5: % of POs budget-checked at request; full-year forecast accuracy | O5: 100% of POs; within ±5% by Q3
A6: RE-02 | B6: One digital Delegation of Authority matrix | C6: All | D6: Sequential approval chains defined per document type (e.g., LAD Officer → Head → Legal → Finance → CFO/CEO; Dept Head → OM → Budget Authority), largely on paper and email. | E6: Long cycle times. Documents wait in inboxes with no visibility of where they are stuck. Thresholds differ by department. | F6: One Board-approved DOA matrix by document type, amount and risk, configured once in Odoo. Independent reviews (e.g., Legal and Finance) run in parallel. Approval SLAs with auto-escalation. Low-value, in-budget items auto-approved and sampled monthly. | G6: Removes waiting time, not controls. Every approval is visible with timestamps. One matrix to maintain instead of department-specific rules. | H6: Requester ≠ approver enforced by the system. Thresholds set by the Board. Monthly post-approval sampling by Internal Audit. Delegations have end dates. | I6: Efficiency, Transparency | J6: Wave 0 – Now (before BRD) | K6: Wave 1 | L6: Approvals, Studio rules, activity SLAs | M6: Covered (§3.4 approval matrices); PHI defines the DOA | N6: Median approval cycle time; % approvals within SLA | O6: ≤ 2 working days; ≥ 90% within SLA
A7: RE-03 | B7: Two-stage land due diligence with deal scorecard | C7: 04 | D7: Due diligence on title, survey, zoning and appraisal runs largely one step after another before ManCom evaluates the deal. | E7: Fatal flaws (title defects, CARP/DAR coverage, no road access) surface late, after DD spend. ManCom compares deals presented in different formats. | F7: Stage 1: screen knock-out criteria (title, CARP/DAR, zoning, access) within days. Stage 2: run the full DD workstreams in parallel. Present every deal to ManCom on one standard scorecard (price, yield, risks). One digital deal room per parcel. | G7: Weak deals stop early, cutting wasted DD cost. Standard scorecards let ManCom decide faster and compare like with like. | H7: Gate decisions recorded. DD evidence retained per parcel. Broker conflict-of-interest declarations. | I7: Efficiency, Transparency | J7: Wave 0 – Now (before BRD) | K7: Wave 1 | L7: Land Acquisition (lam.lot), DD checklist, Documents | M7: Covered (§3.3 #19–21) | N7: Days from opportunity logged to go/no-go; DD spend on rejected deals | O7: Go/no-go ≤ 15 working days
A8: RE-04 | B8: Evidence-based land payments and filing calendar | C8: 04 | D8: Milestone payments released on request; tax filings and title transfer tracked manually. | E8: Risk of paying before conditions are met. Surcharges for late filings. Little visibility of titles in transit. | F8: Release a milestone payment only when its evidence is uploaded and verified by Legal. Generate a statutory filing calendar (CGT, DST, transfer tax, RD) automatically at deed signing. Keep a titles-in-transit register. | G8: Paying on evidence prevents premature payments. The calendar avoids penalties. ManCom sees which titles are at risk. | H8: Legal verifies evidence independently of the requester. Each filing closed with proof of payment. | I8: Transparency, Efficiency | J8: Wave 1 – Odoo build (2027 rollout) | L8: Land Acquisition, Approvals, Documents | M8: Covered (§3.3 #24, #26, #60) | N8: Filing penalties paid; % milestone payments with verified evidence | O8: Zero penalties; 100%
A9: RE-05 | B9: Project templates and a hard License-to-Sell gate | C9: 05 | D9: Each project is set up with its own structure. Permits are tracked separately and selling readiness is judged case by case. | E9: Inconsistent WBS and cost codes make cross-project comparison hard. Risk of selling before the License to Sell is issued. | F9: Project templates by type (horizontal, vertical, mixed-use) that clone WBS, cost codes, milestones and required documents. A launch gate with DP and License to Sell as hard criteria before any reservation can be made. | G9: Setup takes hours instead of weeks, and every project reports the same way. Regulatory exposure from pre-selling is eliminated. | H9: PD 957: system blocks reservations without an LTS. Gate approval logged. | I9: Efficiency, Reporting, Transparency | J9: Wave 0 – Now (before BRD) | K9: Wave 1 | L9: Project setup wizard, launch-readiness gate | M9: Partial — LTS gate is Appendix A7 | N9: Project setup time; reservations made before LTS | O9: ≤ 5 working days; zero
A10: RE-06 | B10: One Group cost-code structure | C10: 01, 06, 16, X2 | D10: Budget, POs, bills and reports may use different cost categories by project or department. | E10: Project P&L and cost-per-sqm benchmarks need manual mapping. Data migration becomes harder. | F10: One Group cost breakdown structure and set of analytic plans, used identically in budget, PO, bill, progress billing and reports. Owned by Finance with change control. | G10: Enables automatic drill-down project P&L and benchmarking across projects and Group affiliates. It is a foundation of the Odoo data model, so it must be settled before BRD. | H10: Cost-code changes need Finance approval. Analytic account mandatory on every cost line, enforced by the system. | I10: Reporting, Transparency | J10: Wave 0 – Now (before BRD) | K10: Wave 1 | L10: Analytic plans, Chart of Accounts | M10: Covered (§3.1 F, G analytic enforcement) | N10: % of cost lines with a valid cost code | O10: 100%
A11: RE-07 | B11: Measure construction progress once, use it three times | C11: 06, 07, Finance | D11: Contractor submits an accomplishment report, QS verifies, progress billing is processed, and unit construction status is updated separately. | E11: The same progress is measured and keyed several times. Disputes over % complete. Revenue (POC) and inventory status lag reality. | F11: One joint site verification per billing cycle, captured on mobile with geotagged photos and % per BOQ line. The verified % drives progress billing (with retention and recoupment), unit construction status, and the POC input for revenue. | G11: One measurement feeds three processes, removing re-keying and reconciliations. Photo evidence reduces disputes. | H11: QS verification independent of the project team. Contractors cannot bill above verified %. Retention and recoupment computed, not typed. | I11: Efficiency, Transparency, Reporting | J11: Wave 1 – Odoo build (2027 rollout) | L11: Project, Purchase, progress photo gallery | M11: Partial — recoupment/VOs are Appendix A6 | N11: Days from cut-off to approved progress billing; billing disputes | O11: ≤ 7 days
A12: RE-08 | B12: Pricing governance and a single price source | C12: 07 | D12: Price lists maintained per project; discounts approved case by case. | E12: Margin leakage from discounts. Inconsistent approvals. Brokers sometimes quote outdated prices. | F12: Price floor per lot, a discount matrix by authority level, and scheduled price escalations per phase approved by ManCom. Live availability and prices published to brokers only through the portal. | G12: Protects margin. One version of price and availability for everyone. Fewer calls to Sales admin. | H12: System blocks under-floor quotes. Discounts beyond the matrix need DOA approval. Price changes logged. | I12: Transparency, Efficiency | J12: Wave 0 – Now (before BRD) | K12: Wave 1 | L12: Pricelists, pricing rules engine, broker portal | M12: Covered (§3.1 D, H; §3.3 #49) | N12: Average discount vs list; % of sales with exception discounts | O12: Exception discounts < 5% of sales
A13: RE-09 | B13: Digital deal jacket from reservation to CTS | C13: 09 | D13: Reservation, then document collection, credit check, CTS drafting and notarization in sequence, mostly on paper. | E13: Long reservation-to-CTS cycle. Buyers asked for documents repeatedly. Retyping errors in the CTS. Collections start late. | F13: Buyer uploads KYC and financing documents at reservation (portal with OCR). Completeness checklist per financing scheme. CTS generated from the confirmed sales order with no retyping. Weekly notarization batches. SLA dashboard from reservation to notarized CTS. | G13: Cuts cycle time and errors. Buyers submit documents once. Management sees the aging of unsigned CTSs. | H13: Data Privacy Act (RA 10173) consent and access controls on buyer data. CTS still notarized. Changes after generation need approval. | I13: Efficiency, Transparency | J13: Wave 1 – Odoo build (2027 rollout) | L13: CRM, Sales, Sign, Documents (OCR), buyer portal | M13: Partial — CTS generation is Appendix A2 | N13: Days from reservation to notarized CTS; % of documents complete at reservation | O13: ≤ 30 days; ≥ 80%
A14: RE-10 | B14: Electronic collections with automatic bank matching | C14: 11 | D14: Buyers pay at the cashier or by check/PDC. Cashier issues receipts. Posting and bank matching are manual. | E14: PDC handling and bounced checks. Posting delays make SOAs stale. High cashier workload. | F14: Move buyers to electronic payment using per-buyer bank references (InstaPay, PESONet, bank over-the-counter). Daily bank file (CSV/MT940) auto-matched to the buyer ledger. Invoice issued on posting. Cashier handles exceptions only. No PDCs for new buyers. | G14: Same-day posting and accurate SOAs. Fewer bounced checks. Less cash-handling risk. | H14: Daily bank reconciliation. Separate duties for receipting, posting and reconciliation. BIR-registered invoice series (EOPT). | I14: Efficiency, Transparency, Reporting | J14: Wave 0 – Now (before BRD) | K14: Wave 1 | L14: Accounting bank import (CSV/MT940), reconciliation models | M14: Partial — bank file import in scope; gateway out of scope (§9) | N14: % of collections received electronically; posting lag | O14: ≥ 70% within 12 months; ≤ 1 working day
A15: RE-11 | B15: Collections playbook by aging bucket | C15: 11, 12 | D15: Aging reports reviewed; demand letters prepared manually; cancellation when default persists. | E15: Late intervention. Inconsistent treatment of buyers. Cancellations that could have been saved. | F15: Automated reminders before and after due date. Account officer assigned at 30 days past due. Restructuring offer before 60 days. Maceda notice clock started automatically when criteria are met. | G15: Earlier contact reduces cancellations and refunds. Uniform, defensible treatment. Clear workload per collector. | H15: Penalty waivers and restructuring need DOA approval. RA 6552 grace periods and notices tracked by the system. Full contact log. | I15: Efficiency, Transparency | J15: Wave 0 – Now (before BRD) | K15: Wave 1 | L15: Payment reminders, customer loans, activities | M15: Partial — demand letters A5, Maceda A1 | N15: Accounts > 60 days past due; cancellation rate | O15: Set after baseline; e.g., −25% in year one
A16: RE-12 | B16: Same-week cancellation and re-listing | C16: 12 | D16: Cancellation computed and approved manually; unit returned to inventory afterwards. | E16: Slow refunds and re-listing. Computation errors. No insight into why buyers cancel. | F16: Workflow computes cash surrender value, deductions and commission clawback automatically. Unit re-priced and re-listed the day cancellation takes effect. Cancellation reason codes mandatory. | G16: Inventory recycles faster. Statutory computation is consistent. Reason codes inform sales and product decisions. | H16: Maceda computation rules locked. Refund approval per DOA. Reversal journals automatic and auditable. | I16: Efficiency, Reporting | J16: Wave 1 – Odoo build (2027 rollout) | L16: Sales, Accounting, custom cancellation workflow | M16: Gap — Appendix A1 | N16: Days from effective cancellation to re-listing | O16: ≤ 5 working days
A17: RE-13 | B17: Start loan takeout at reservation | C17: 13 | D17: Loan documents collected after equity is fully paid; takeout tracked by the Loans team. | E17: Loan approval risk found late. Long gap between equity completion and cash release — PHI's largest single inflow waits. | F17: Bank / Pag-IBIG pre-qualification at reservation. Loan document pack built during the equity period. Takeout pipeline with lender SLAs and a weekly review. DOAS and title annotation prepared in parallel with lender approval. | G17: Shorter cash conversion cycle. Financing failures detected months earlier, with time to re-route the buyer. | H17: Buyer consent for credit checks (Data Privacy Act). Lender correspondence retained. Proceeds matched to the buyer ledger. | I17: Efficiency, Transparency, Reporting | J17: Wave 0 – Now (before BRD) | K17: Wave 1 | L17: Customer Loans & Financing, Documents | M17: Partial — Appendix A4 | N17: Days from equity fully paid to loan release; takeout failure rate | O17: ≤ 60 days
A18: RE-14 | B18: Hands-off commission cycle | C18: 17 | D18: Commissions computed and released by tranche; brokers call for status. | E18: Manual computation and disputes. Broker follow-up calls. Clawbacks hard to enforce. | F18: Use the SOW commission engine fully: compute at CTS, release automatically when collection thresholds are hit, broker self-service statements, broker invoice upload before payout, and automatic clawback netting on cancellation. | G18: Removes manual work and disputes, and builds broker trust. | H18: EWT computed automatically. Broker BIR invoice required before payment. Clawbacks enforced by netting. | I18: Efficiency, Transparency | J18: Wave 1 – Odoo build (2027 rollout) | L18: Sales commissions, broker portal | M18: Covered (§3.3 #41–47, #53) | N18: Days from release trigger to payout; disputes per month | O18: ≤ 10 days
A19: RE-15 | B19: No PO, no pay — with scheduled payment runs | C19: 03, 06, 16 | D19: Requests, POs and bills processed with manual matching; payments released as prepared. | E19: Bills without POs. Duplicate-payment risk. Frequent ad hoc payment runs. | F19: 'No PO, no pay' policy with defined exemptions (utilities, government fees). Mandatory 3-way match (PO – receipt or accomplishment – bill). Two scheduled payment runs a week. BIR 2307 generated and emailed automatically. | G19: Fewer exceptions and less rework. Predictable cash outflow. Suppliers get 2307s without asking. | H19: Duplicate bill detection. Payment runs approved as a batch per DOA. Tolerance limits on price and quantity variances. | I19: Efficiency, Transparency | J19: Wave 0 – Now (before BRD) | K19: Wave 1 | L19: Purchase, Accounting (batch payments), PH localization | M19: Covered — confirm 2307 outputs (A9) | N19: % of eligible spend on a PO; ad hoc payment runs per month | O19: ≥ 95%; ≤ 2
A20: RE-16 | B20: Independent vendor master with bank-change verification | C20: 16 | D20: Vendor records and bank details may be maintained by the same users who process payments (to be validated). | E20: Payment-fraud risk from unauthorized bank-detail changes. Duplicate vendors distort spend data. | F20: Central vendor master function. Accreditation through the supplier workflow. Bank-detail changes need a callback verification and a second approval. Duplicate TIN check. | G20: Closes a common payment-fraud route and keeps vendor data clean for spend analytics. | H20: Separation between vendor master maintenance and payments. Change log reviewed monthly. | I20: Transparency | J20: Wave 0 – Now (before BRD) | K20: Wave 1 | L20: Contacts, supplier accreditation workflow, access rules | M20: Covered (§3.1 F accreditation) | N20: Bank-detail changes without verification; duplicate vendors | O20: Zero
A21: RE-17 | B21: TORC paid directly, recharged automatically | C21: 14 | D21: Taxes and other related charges paid through cash advances, then liquidated; recharge to the buyer handled separately. | E21: Outstanding cash advances. Missed recharges. Manual computation per title. | F21: Standard TORC computation per lot generated from deed values. Pay agencies directly through AP or e-payment channels where available instead of cash advances. Recharge posted to the buyer ledger automatically. | G21: Less cash exposure, no missed recharges, faster liquidation. | H21: No new advance while a liquidation is overdue. Aging of unliquidated advances. Computation audit trail. | I21: Efficiency, Transparency | J21: Wave 0 – Now (before BRD) | K21: Wave 1 | L21: Accounting, Approvals, TORC budget | M21: Confirm — Appendix B1 | N21: Unliquidated advances > 30 days; % of TORC recharged | O21: Zero; 100%
A22: RE-18 | B22: One handover pipeline from RFO to title | C22: 15, 19 | D22: Turnover and title processing handled by different teams with separate tracking. | E22: Buyers chase status by phone. Titles are delayed. No end-to-end view. | F22: One pipeline from ready-for-occupancy to title delivery with stage SLAs. Batch title processing per phase (bulk eCAR and RD submissions). Status visible to the buyer in the portal. | G22: Fewer status calls. Batching cuts per-title time and cost. Management sees the bottlenecks. | H22: Title custody log (who holds each title). Release only to the buyer or lender with signed acknowledgment. | I22: Efficiency, Transparency, Reporting | J22: Wave 1 – Odoo build (2027 rollout) | L22: Helpdesk, buyer portal, title tab | M22: Partial — processing is Appendix A10 | N22: Days from full payment to title delivery | O22: Set after baseline
A23: RE-19 | B23: Automated monthly revenue recognition | C23: Finance | D23: Percentage-of-completion revenue prepared in spreadsheets at period end (to be validated). | E23: Audit adjustments. Slower close. Method applied inconsistently. | F23: Compute POC revenue monthly from the single verified progress source (RE-07) and the collectability threshold, using a method agreed with the external auditor. | G23: Removes a spreadsheet-heavy step from the close and reduces audit adjustments. | H23: PFRS 15. Method documented and approved. Review before posting. | I23: Reporting, Efficiency | J23: Wave 1 – Odoo build (2027 rollout) | L23: Accounting, Project | M23: Gap — Appendix A3 | N23: Audit adjustments on revenue | O23: No material adjustments
A24: RE-20 | B24: Fast close and one management pack | C24: X2 | D24: Month-end relies on manual consolidation across departments (as described in SOW §2). | E24: Slow close. Management packs assembled by hand. Numbers differ between reports. | F24: Close calendar and checklist with named owners. Sub-ledgers post automatically. Intercompany transactions matched across Group entities. Standard management pack generated from Odoo. One KPI dictionary for all reports. | G24: Faster, consistent numbers and Finance time freed for analysis. | H24: Close checklist sign-offs. Reconciliations evidenced. Periods locked after close. | I24: Reporting, Efficiency, Transparency | J24: Wave 0 – Now (before BRD) | K24: Wave 1 → 2 | L24: Accounting (lock dates, intercompany), Spreadsheet dashboards | M24: Covered (§3.1 G company performance report) | N24: Working days to close | O24: ≤ 5 at go-live; ≤ 3 after hypercare
A25: RE-21 | B25: Rolling 13-week cash forecast | C25: X1, 02 | D25: Cash-flow projections prepared periodically. | E25: Treasury decisions made on stale information; borrowing timed conservatively. | F25: Weekly 13-week cash forecast built from system schedules: buyer amortizations, takeout pipeline, AP due dates and loan service. Weekly Treasury review. | G25: Better timing of borrowing and payments; lower financing cost. | H25: Forecast versions retained; variance to actual reviewed weekly. | I25: Reporting, Transparency | J25: Wave 1 – Odoo build (2027 rollout) | K25: Wave 2 | L25: Spreadsheet, Accounting, Customer and Company Loans | M25: Partial — Appendix A13 | N25: Forecast accuracy at week +4 | O25: Within ±10%
A26: RE-22 | B26: Data ownership and clean-up before migration | C26: All | D26: Data is owned by whoever enters it; legacy data in In4 Velocity varies in quality. | E26: Migration quality decides go-live success. Under the SOW 'CSV Rule', dirty data costs flex days. | F26: Named data owners for the Lot, buyer, vendor and cost-code masters. Monthly data-quality scorecard. Start cleansing legacy data now: duplicates, missing TINs, buyer-ledger reconciliation to GL. | G26: Cleaner migration, fewer flex days, and trustworthy reports from day one. | H26: Master-data changes approved and logged. Reconciled opening balances signed off by Finance. | I26: Reporting, Efficiency | J26: Wave 0 – Now (before BRD) | K26: Wave 1 | L26: Data migration templates | M26: Client obligation (SOW §7, §8) | N26: Error rate in mock migration loads | O26: < 2% by the final mock load
A27: RE-23 | B27: Named process owners with KPIs | C27: All | D27: Processes are run by departments; performance is not measured per end-to-end process. | E27: Improvements fade after go-live; no one owns cross-department hand-offs. | F27: Every blueprint process has a named owner and 2–3 KPIs. Monthly process performance review. Improvement backlog kept in the blueprint web app. | G27: Sustains the gains beyond go-live and makes hand-off problems visible. | H27: KPI definitions controlled in the KPI dictionary; review minutes retained. | I27: Transparency, Reporting | J27: Wave 0 – Now (before BRD) | K27: Wave 2 | L27: Blueprint web app, Odoo dashboards | M27: Policy — no SOW impact | N27: % of processes with an owner and a KPI baseline | O27: 100% before BRD

Sheet Before-After Detail
A1: Before and after — how each re-engineering changes the process, and why
A2: Step tags — Before: [Manual] done by hand · [Paper] paper document · [Rekey] same data typed again · [Wait] queue or delay. After: [Auto] system does it · [Rule] system-enforced control · [Parallel] runs at the same time · [Earlier] moved earlier · [New] new step · [Same] unchanged.
A4: ID | B4: Opportunity | C4: Blueprint process | D4: Current process (summary) | E4: Proposed process (summary) | F4: 1a. Why change: problem and root cause | G4: 1b. How the re-engineering fixes it | H4: 1c. Effect on controls and compliance | I4: 1d. Expected outcome (KPI → target) | J4: 2a. BEFORE — current process steps | K4: 2b. AFTER — re-engineered process steps | L4: 2c. What changes | M4: 2d. Roles affected and how | N4: Steps before | O4: Steps after | P4: Manual, paper, re-key or wait steps before | Q4: Automated or system-enforced steps after | R4: Steps moved earlier or run in parallel
A5: RE-01 | B5: =VLOOKUP(A5,'Re-engineering Map'!$A$5:$O$27,2,FALSE()) -> Driver-based budget with commitment control | C5: =VLOOKUP(A5,'Re-engineering Map'!$A$5:$O$27,3,FALSE()) -> 01 | D5: =VLOOKUP(A5,'Re-engineering Map'!$A$5:$O$27,4,FALSE()) -> Annual static budget: departments and PDD fill templates, Finance consolidates, ManCom approves. Spending is checked against budget mainly when the bill arrives. | E5: =VLOOKUP(A5,'Re-engineering Map'!$A$5:$O$27,6,FALSE()) -> Build the budget from drivers (units, prices, cost per sqm, headcount) and reforecast quarterly. Check budget availability at purchase request and reserve the amount (commitment control). | F5: The budget is a once-a-year spreadsheet with no link to what PHI actually commits. Spend is checked only when bills post, after PHI is already contractually committed, so the budget reports variances but cannot prevent them. | G5: A driver model ties the budget to operational reality (units sold, cost per sqm), so a change in drivers updates the budget instead of forcing a re-budget. Checking and reserving budget at the purchase request stops overspend at the cheapest point — before a supplier is engaged. | H5: Strengthens control: a detective check (variance after posting) becomes a preventive one (block or escalate before commitment). Baseline versions and every override are logged for audit. | I5: =VLOOKUP(A5,'Re-engineering Map'!$A$5:$O$27,14,FALSE())&" → "&VLOOKUP(A5,'Re-engineering Map'!$A$5:$O$27,15,FALSE()) -> % of POs budget-checked at request; full-year forecast accuracy → 100% of POs; within ±5% by Q3 | J5: 1. [Manual] Finance issues budget templates to departments and PDD 2. [Manual] Departments fill in templates line by line 3. [Rekey] Finance consolidates spreadsheets into one file 4. ManCom reviews and approves the annual budget 5. [Manual] Purchase request raised with no budget check 6. [Manual] PO issued; supplier delivers; bill received 7. [Wait] Overspend found when the bill posts against the budget report 8. [Manual] Budget realignment requested after the fact | K5: 1. [New] Finance sets budget drivers (units, prices, cost per sqm, headcount) 2. [Same] Departments and PDD enter or adjust drivers and assumptions 3. [Auto] System computes and consolidates budget lines from drivers 4. [Same] ManCom approves; baseline locked and versioned 5. [Rule] Purchase request checked against available budget; amount reserved 6. [Rule] Requests over budget routed to the DOA approver before any PO 7. [Auto] PO and bill consume the reserved commitment 8. [New] Quarterly reforecast updates drivers and explains variances | L5: Consolidation automated. Budget check moved from the bill to the purchase request. After-the-fact realignment replaced by approval before commitment. Quarterly reforecast added. | M5: Finance: from consolidating spreadsheets to maintaining drivers and explaining variances. Requesters: see available budget when they raise a request. Department heads: approve reforecasts. | N5: =LEN(J5)-LEN(SUBSTITUTE(J5,CHAR(10),""))+1 -> 8 | O5: =LEN(K5)-LEN(SUBSTITUTE(K5,CHAR(10),""))+1 -> 8 | P5: =(LEN(J5)-LEN(SUBSTITUTE(J5,"[Manual]","")))/8+(LEN(J5)-LEN(SUBSTITUTE(J5,"[Paper]","")))/7+(LEN(J5)-LEN(SUBSTITUTE(J5,"[Rekey]","")))/7+(LEN(J5)-LEN(SUBSTITUTE(J5,"[Wait]","")))/6 -> 7 | Q5: =(LEN(K5)-LEN(SUBSTITUTE(K5,"[Auto]","")))/6+(LEN(K5)-LEN(SUBSTITUTE(K5,"[Rule]","")))/6 -> 4 | R5: =(LEN(K5)-LEN(SUBSTITUTE(K5,"[Earlier]","")))/9+(LEN(K5)-LEN(SUBSTITUTE(K5,"[Parallel]","")))/10 -> 0
A6: RE-02 | B6: =VLOOKUP(A6,'Re-engineering Map'!$A$5:$O$27,2,FALSE()) -> One digital Delegation of Authority matrix | C6: =VLOOKUP(A6,'Re-engineering Map'!$A$5:$O$27,3,FALSE()) -> All | D6: =VLOOKUP(A6,'Re-engineering Map'!$A$5:$O$27,4,FALSE()) -> Sequential approval chains defined per document type (e.g., LAD Officer → Head → Legal → Finance → CFO/CEO; Dept Head → OM → Budget Authority), largely on paper and email. | E6: =VLOOKUP(A6,'Re-engineering Map'!$A$5:$O$27,6,FALSE()) -> One Board-approved DOA matrix by document type, amount and risk, configured once in Odoo. Independent reviews (e.g., Legal and Finance) run in parallel. Approval SLAs with auto-escalation. Low-value, in-budget items auto-approved and sampled monthly. | F6: Approval rules differ by department and live in people's heads or on paper routing slips. Approvals run one after another even when reviewers check unrelated things, and nobody can see where a document is waiting. | G6: One matrix means one set of limits to maintain and audit. Parallel review removes queueing time without removing any reviewer. SLAs and escalation make delays visible. Auto-approval with sampling focuses senior attention on high-value, high-risk items. | H6: Maintains or strengthens control: approvers and limits come from a Board-approved matrix; the system prevents self-approval; every decision is timestamped; Internal Audit samples auto-approved items monthly. | I6: =VLOOKUP(A6,'Re-engineering Map'!$A$5:$O$27,14,FALSE())&" → "&VLOOKUP(A6,'Re-engineering Map'!$A$5:$O$27,15,FALSE()) -> Median approval cycle time; % approvals within SLA → ≤ 2 working days; ≥ 90% within SLA | J6: 1. [Paper] Requester prepares document and routing slip 2. [Manual] Document passed to first approver 3. [Wait] Waits in first approver's inbox 4. [Manual] Passed to second approver (e.g., Legal) 5. [Wait] Waits; then passed to third approver (e.g., Finance) 6. [Wait] Waits; then passed to final approver (CFO/CEO) 7. [Manual] Requester follows up by phone to find the document | K6: 1. [Same] Requester submits document in Odoo 2. [Auto] System selects approvers from the DOA matrix by type, amount and risk 3. [Rule] Low-value, in-budget items auto-approved and flagged for sampling 4. [Parallel] Independent reviewers (e.g., Legal and Finance) approve at the same time 5. [Rule] Approval SLA timer; auto-escalation when overdue 6. [Same] Final approver approves 7. [Auto] Status and full approval history visible to requester | L6: Routing slips and follow-up calls removed. Approver selection automated. Sequential reviews made parallel where independent. Escalation and sampling added. | M6: Approvers: see only items they must decide, with deadlines. Requesters: track status without calling. Internal Audit: new monthly sampling of auto-approved items. Board: approves the DOA matrix. | N6: =LEN(J6)-LEN(SUBSTITUTE(J6,CHAR(10),""))+1 -> 7 | O6: =LEN(K6)-LEN(SUBSTITUTE(K6,CHAR(10),""))+1 -> 7 | P6: =(LEN(J6)-LEN(SUBSTITUTE(J6,"[Manual]","")))/8+(LEN(J6)-LEN(SUBSTITUTE(J6,"[Paper]","")))/7+(LEN(J6)-LEN(SUBSTITUTE(J6,"[Rekey]","")))/7+(LEN(J6)-LEN(SUBSTITUTE(J6,"[Wait]","")))/6 -> 7 | Q6: =(LEN(K6)-LEN(SUBSTITUTE(K6,"[Auto]","")))/6+(LEN(K6)-LEN(SUBSTITUTE(K6,"[Rule]","")))/6 -> 4 | R6: =(LEN(K6)-LEN(SUBSTITUTE(K6,"[Earlier]","")))/9+(LEN(K6)-LEN(SUBSTITUTE(K6,"[Parallel]","")))/10 -> 1
A7: RE-03 | B7: =VLOOKUP(A7,'Re-engineering Map'!$A$5:$O$27,2,FALSE()) -> Two-stage land due diligence with deal scorecard | C7: =VLOOKUP(A7,'Re-engineering Map'!$A$5:$O$27,3,FALSE()) -> 04 | D7: =VLOOKUP(A7,'Re-engineering Map'!$A$5:$O$27,4,FALSE()) -> Due diligence on title, survey, zoning and appraisal runs largely one step after another before ManCom evaluates the deal. | E7: =VLOOKUP(A7,'Re-engineering Map'!$A$5:$O$27,6,FALSE()) -> Stage 1: screen knock-out criteria (title, CARP/DAR, zoning, access) within days. Stage 2: run the full DD workstreams in parallel. Present every deal to ManCom on one standard scorecard (price, yield, risks). One digital deal room per parcel. | F7: Due diligence runs as one long sequence, so a fatal flaw (title defect, CARP coverage, no access) may only surface after surveys and appraisals are paid for. ManCom receives deals in different formats, which slows decisions. | G7: A short knock-out screen kills doomed deals within days. Running the remaining DD workstreams in parallel shortens the elapsed time. A standard scorecard lets ManCom compare deals on the same terms and decide in one sitting. | H7: Strengthens governance: every gate decision and its evidence is recorded per parcel; broker conflicts of interest are declared up front. | I7: =VLOOKUP(A7,'Re-engineering Map'!$A$5:$O$27,14,FALSE())&" → "&VLOOKUP(A7,'Re-engineering Map'!$A$5:$O$27,15,FALSE()) -> Days from opportunity logged to go/no-go; DD spend on rejected deals → Go/no-go ≤ 15 working days | J7: 1. [Manual] Land opportunity received from broker or owner 2. [Manual] Title verification requested 3. [Wait] Survey commissioned after title check 4. [Wait] Zoning and access verified after survey 5. [Wait] Appraisal commissioned 6. [Manual] Deal memo prepared in its own format 7. ManCom evaluates; fatal flaws sometimes found late | K7: 1. [Same] Land opportunity logged in the land module 2. [New] Knock-out screen: title, CARP/DAR, zoning, access (days, not weeks) 3. [Rule] Deals failing any knock-out closed with reason 4. [Parallel] Title, survey, zoning and appraisal run at the same time 5. [Auto] DD results populate the standard deal scorecard 6. ManCom decides go/no-go on the scorecard 7. [Auto] Evidence kept in the parcel's deal room | L7: Knock-out screen added up front. Sequential DD made parallel. Custom deal memos replaced by a standard scorecard. | M7: Land acquisition: runs the screen and coordinates parallel DD. Legal, surveyors, appraisers: work in parallel. ManCom: decides from one format. | N7: =LEN(J7)-LEN(SUBSTITUTE(J7,CHAR(10),""))+1 -> 7 | O7: =LEN(K7)-LEN(SUBSTITUTE(K7,CHAR(10),""))+1 -> 7 | P7: =(LEN(J7)-LEN(SUBSTITUTE(J7,"[Manual]","")))/8+(LEN(J7)-LEN(SUBSTITUTE(J7,"[Paper]","")))/7+(LEN(J7)-LEN(SUBSTITUTE(J7,"[Rekey]","")))/7+(LEN(J7)-LEN(SUBSTITUTE(J7,"[Wait]","")))/6 -> 6 | Q7: =(LEN(K7)-LEN(SUBSTITUTE(K7,"[Auto]","")))/6+(LEN(K7)-LEN(SUBSTITUTE(K7,"[Rule]","")))/6 -> 3 | R7: =(LEN(K7)-LEN(SUBSTITUTE(K7,"[Earlier]","")))/9+(LEN(K7)-LEN(SUBSTITUTE(K7,"[Parallel]","")))/10 -> 1
A8: RE-04 | B8: =VLOOKUP(A8,'Re-engineering Map'!$A$5:$O$27,2,FALSE()) -> Evidence-based land payments and filing calendar | C8: =VLOOKUP(A8,'Re-engineering Map'!$A$5:$O$27,3,FALSE()) -> 04 | D8: =VLOOKUP(A8,'Re-engineering Map'!$A$5:$O$27,4,FALSE()) -> Milestone payments released on request; tax filings and title transfer tracked manually. | E8: =VLOOKUP(A8,'Re-engineering Map'!$A$5:$O$27,6,FALSE()) -> Release a milestone payment only when its evidence is uploaded and verified by Legal. Generate a statutory filing calendar (CGT, DST, transfer tax, RD) automatically at deed signing. Keep a titles-in-transit register. | F8: Payments to landowners are released on request, so evidence that the milestone was met may be checked late or informally. Tax and title filings are tracked manually, which risks surcharges and lost visibility of titles in transit. | G8: Payment requests cannot be created until evidence is uploaded and verified. The filing calendar is generated automatically from the deed, so deadlines are never missed. A titles-in-transit register shows where every title is. | H8: Strengthens control: pay-on-evidence is preventive; verification by Legal separates duties from the requester; each filing closes only with proof of payment (BIR, LGU, RD). | I8: =VLOOKUP(A8,'Re-engineering Map'!$A$5:$O$27,14,FALSE())&" → "&VLOOKUP(A8,'Re-engineering Map'!$A$5:$O$27,15,FALSE()) -> Filing penalties paid; % milestone payments with verified evidence → Zero penalties; 100% | J8: 1. [Manual] Landowner or broker requests milestone payment 2. [Manual] Land team prepares payment request 3. [Manual] Evidence of milestone checked informally, if at all 4. Payment approved and released 5. [Manual] Tax filings tracked in a personal spreadsheet 6. [Wait] Late filing discovered; surcharge paid 7. [Manual] Title status found by asking the liaison | K8: 1. [Rule] Milestone evidence uploaded against the milestone 2. [New] Legal verifies evidence 3. [Auto] Payment request created only after verification 4. [Same] Payment approved per DOA and released 5. [Auto] Filing calendar (CGT, DST, transfer tax, RD) generated at deed signing 6. [Auto] Reminders before each deadline; filing closed with proof of payment 7. [Auto] Title-in-transit register updated at each step | L8: Informal evidence check replaced by a verification gate. Filing tracking automated with reminders. Title status made visible. | M8: Legal: new verification step before payment. Land team: uploads evidence instead of chasing approvals. Finance: pays only verified milestones. | N8: =LEN(J8)-LEN(SUBSTITUTE(J8,CHAR(10),""))+1 -> 7 | O8: =LEN(K8)-LEN(SUBSTITUTE(K8,CHAR(10),""))+1 -> 7 | P8: =(LEN(J8)-LEN(SUBSTITUTE(J8,"[Manual]","")))/8+(LEN(J8)-LEN(SUBSTITUTE(J8,"[Paper]","")))/7+(LEN(J8)-LEN(SUBSTITUTE(J8,"[Rekey]","")))/7+(LEN(J8)-LEN(SUBSTITUTE(J8,"[Wait]","")))/6 -> 6 | Q8: =(LEN(K8)-LEN(SUBSTITUTE(K8,"[Auto]","")))/6+(LEN(K8)-LEN(SUBSTITUTE(K8,"[Rule]","")))/6 -> 5 | R8: =(LEN(K8)-LEN(SUBSTITUTE(K8,"[Earlier]","")))/9+(LEN(K8)-LEN(SUBSTITUTE(K8,"[Parallel]","")))/10 -> 0
A9: RE-05 | B9: =VLOOKUP(A9,'Re-engineering Map'!$A$5:$O$27,2,FALSE()) -> Project templates and a hard License-to-Sell gate | C9: =VLOOKUP(A9,'Re-engineering Map'!$A$5:$O$27,3,FALSE()) -> 05 | D9: =VLOOKUP(A9,'Re-engineering Map'!$A$5:$O$27,4,FALSE()) -> Each project is set up with its own structure. Permits are tracked separately and selling readiness is judged case by case. | E9: =VLOOKUP(A9,'Re-engineering Map'!$A$5:$O$27,6,FALSE()) -> Project templates by type (horizontal, vertical, mixed-use) that clone WBS, cost codes, milestones and required documents. A launch gate with DP and License to Sell as hard criteria before any reservation can be made. | F9: Each project is set up from scratch, so WBS, cost codes and documents differ between projects and cannot be compared. Selling readiness is judged case by case, which risks selling before the License to Sell is issued. | G9: Templates by project type make setup a copy-and-adjust task and guarantee the same structure across projects. A hard launch gate makes the License to Sell a system condition rather than a reminder. | H9: Strengthens compliance: PD 957 requirement enforced by the system — no reservation can be created without an LTS. Gate approvals logged. | I9: =VLOOKUP(A9,'Re-engineering Map'!$A$5:$O$27,14,FALSE())&" → "&VLOOKUP(A9,'Re-engineering Map'!$A$5:$O$27,15,FALSE()) -> Project setup time; reservations made before LTS → ≤ 5 working days; zero | J9: 1. [Manual] Project team designs WBS and cost codes for the new project 2. [Manual] Finance creates accounts and analytic structure 3. [Manual] Permits tracked in a separate spreadsheet 4. [Manual] Sales told informally the project may launch 5. [Wait] Reservations may start while LTS is pending | K9: 1. [Same] Project team selects the template for the project type 2. [Auto] WBS, cost codes, milestones and required documents cloned 3. [Same] Team adjusts project-specific details 4. [New] Permit register tracks DP, ECC, BP, CR/LTS 5. [Rule] Launch gate blocks reservations until DP and LTS are recorded 6. [Auto] Sales notified when the gate passes | L9: Manual structure design replaced by templates. Permits moved into the system. Informal launch replaced by a system gate. | M9: Project Development: configures from templates. Finance: approves template changes only. Sales: can reserve only after the gate passes. Legal/permits: maintains the permit register. | N9: =LEN(J9)-LEN(SUBSTITUTE(J9,CHAR(10),""))+1 -> 5 | O9: =LEN(K9)-LEN(SUBSTITUTE(K9,CHAR(10),""))+1 -> 6 | P9: =(LEN(J9)-LEN(SUBSTITUTE(J9,"[Manual]","")))/8+(LEN(J9)-LEN(SUBSTITUTE(J9,"[Paper]","")))/7+(LEN(J9)-LEN(SUBSTITUTE(J9,"[Rekey]","")))/7+(LEN(J9)-LEN(SUBSTITUTE(J9,"[Wait]","")))/6 -> 5 | Q9: =(LEN(K9)-LEN(SUBSTITUTE(K9,"[Auto]","")))/6+(LEN(K9)-LEN(SUBSTITUTE(K9,"[Rule]","")))/6 -> 3 | R9: =(LEN(K9)-LEN(SUBSTITUTE(K9,"[Earlier]","")))/9+(LEN(K9)-LEN(SUBSTITUTE(K9,"[Parallel]","")))/10 -> 0
A10: RE-06 | B10: =VLOOKUP(A10,'Re-engineering Map'!$A$5:$O$27,2,FALSE()) -> One Group cost-code structure | C10: =VLOOKUP(A10,'Re-engineering Map'!$A$5:$O$27,3,FALSE()) -> 01, 06, 16, X2 | D10: =VLOOKUP(A10,'Re-engineering Map'!$A$5:$O$27,4,FALSE()) -> Budget, POs, bills and reports may use different cost categories by project or department. | E10: =VLOOKUP(A10,'Re-engineering Map'!$A$5:$O$27,6,FALSE()) -> One Group cost breakdown structure and set of analytic plans, used identically in budget, PO, bill, progress billing and reports. Owned by Finance with change control. | F10: Cost categories differ across budget, purchasing, billing and reporting, so every cross-project report needs manual mapping. This also makes the Odoo data model and migration harder. | G10: A single cost breakdown structure used in every transaction means project P&L and cost-per-sqm benchmarks come straight from the system. Settling it before BRD avoids rebuilding reports later. | H10: Strengthens reporting integrity: analytic tagging mandatory on every cost line; cost-code changes controlled by Finance. | I10: =VLOOKUP(A10,'Re-engineering Map'!$A$5:$O$27,14,FALSE())&" → "&VLOOKUP(A10,'Re-engineering Map'!$A$5:$O$27,15,FALSE()) -> % of cost lines with a valid cost code → 100% | J10: 1. [Manual] Budget uses its own cost categories 2. [Manual] POs coded to different categories 3. [Manual] Bills coded by AP staff judgment 4. [Rekey] Finance maps categories for each project report 5. [Manual] Cross-project benchmarks built by hand | K10: 1. [New] Finance publishes one Group cost-code structure 2. [Rule] Budget, PO, bill and progress billing all require a valid cost code 3. [Auto] Costs roll up by project, phase and cost code 4. [Auto] Project P&L and cost-per-sqm benchmarks generated 5. [Rule] New cost codes added only through Finance change control | L10: Manual mapping removed. Cost code mandatory at every transaction. Benchmarks generated automatically. | M10: Finance: owns the structure. Requesters and AP: choose from one list. Management: gets comparable project reports. | N10: =LEN(J10)-LEN(SUBSTITUTE(J10,CHAR(10),""))+1 -> 5 | O10: =LEN(K10)-LEN(SUBSTITUTE(K10,CHAR(10),""))+1 -> 5 | P10: =(LEN(J10)-LEN(SUBSTITUTE(J10,"[Manual]","")))/8+(LEN(J10)-LEN(SUBSTITUTE(J10,"[Paper]","")))/7+(LEN(J10)-LEN(SUBSTITUTE(J10,"[Rekey]","")))/7+(LEN(J10)-LEN(SUBSTITUTE(J10,"[Wait]","")))/6 -> 5 | Q10: =(LEN(K10)-LEN(SUBSTITUTE(K10,"[Auto]","")))/6+(LEN(K10)-LEN(SUBSTITUTE(K10,"[Rule]","")))/6 -> 4 | R10: =(LEN(K10)-LEN(SUBSTITUTE(K10,"[Earlier]","")))/9+(LEN(K10)-LEN(SUBSTITUTE(K10,"[Parallel]","")))/10 -> 0
A11: RE-07 | B11: =VLOOKUP(A11,'Re-engineering Map'!$A$5:$O$27,2,FALSE()) -> Measure construction progress once, use it three times | C11: =VLOOKUP(A11,'Re-engineering Map'!$A$5:$O$27,3,FALSE()) -> 06, 07, Finance | D11: =VLOOKUP(A11,'Re-engineering Map'!$A$5:$O$27,4,FALSE()) -> Contractor submits an accomplishment report, QS verifies, progress billing is processed, and unit construction status is updated separately. | E11: =VLOOKUP(A11,'Re-engineering Map'!$A$5:$O$27,6,FALSE()) -> One joint site verification per billing cycle, captured on mobile with geotagged photos and % per BOQ line. The verified % drives progress billing (with retention and recoupment), unit construction status, and the POC input for revenue. | F11: Construction progress is measured separately for contractor billing, unit status and revenue, so the same fact is keyed and reconciled several times and the numbers can disagree. | G11: One verified measurement per cycle becomes the single source for billing, inventory status and revenue. Mobile capture with photos provides evidence and shortens disputes. | H11: Strengthens control: QS verification independent of the project team; contractors cannot bill above verified progress; retention and recoupment computed by rule, not typed. | I11: =VLOOKUP(A11,'Re-engineering Map'!$A$5:$O$27,14,FALSE())&" → "&VLOOKUP(A11,'Re-engineering Map'!$A$5:$O$27,15,FALSE()) -> Days from cut-off to approved progress billing; billing disputes → ≤ 7 days | J11: 1. [Paper] Contractor submits accomplishment report 2. [Manual] QS reviews report and visits site 3. [Manual] Progress billing prepared; retention computed by hand 4. [Rekey] Engineering updates unit construction status separately 5. [Rekey] Finance collects % completion again for revenue 6. [Manual] Differences between the three figures reconciled | K11: 1. [Same] Contractor submits billing claim in the portal or system 2. [New] Joint site verification captured on mobile with geotagged photos 3. [Rule] QS verifies % complete per BOQ line 4. [Auto] Progress billing computed with retention and recoupment 5. [Auto] Unit construction status updated from verified % 6. [Auto] Verified % feeds POC revenue input | L11: Two re-keying steps and the reconciliation removed. Retention and recoupment automated. Photo evidence added. | M11: QS: verifies once, on mobile. Engineering: no separate status update. Finance: uses verified % directly. Contractors: bill against verified progress. | N11: =LEN(J11)-LEN(SUBSTITUTE(J11,CHAR(10),""))+1 -> 6 | O11: =LEN(K11)-LEN(SUBSTITUTE(K11,CHAR(10),""))+1 -> 6 | P11: =(LEN(J11)-LEN(SUBSTITUTE(J11,"[Manual]","")))/8+(LEN(J11)-LEN(SUBSTITUTE(J11,"[Paper]","")))/7+(LEN(J11)-LEN(SUBSTITUTE(J11,"[Rekey]","")))/7+(LEN(J11)-LEN(SUBSTITUTE(J11,"[Wait]","")))/6 -> 6 | Q11: =(LEN(K11)-LEN(SUBSTITUTE(K11,"[Auto]","")))/6+(LEN(K11)-LEN(SUBSTITUTE(K11,"[Rule]","")))/6 -> 4 | R11: =(LEN(K11)-LEN(SUBSTITUTE(K11,"[Earlier]","")))/9+(LEN(K11)-LEN(SUBSTITUTE(K11,"[Parallel]","")))/10 -> 0
A12: RE-08 | B12: =VLOOKUP(A12,'Re-engineering Map'!$A$5:$O$27,2,FALSE()) -> Pricing governance and a single price source | C12: =VLOOKUP(A12,'Re-engineering Map'!$A$5:$O$27,3,FALSE()) -> 07 | D12: =VLOOKUP(A12,'Re-engineering Map'!$A$5:$O$27,4,FALSE()) -> Price lists maintained per project; discounts approved case by case. | E12: =VLOOKUP(A12,'Re-engineering Map'!$A$5:$O$27,6,FALSE()) -> Price floor per lot, a discount matrix by authority level, and scheduled price escalations per phase approved by ManCom. Live availability and prices published to brokers only through the portal. | F12: Discounts are approved case by case with no consistent limits, and brokers may quote from outdated price lists, which leaks margin and creates disputes. | G12: A price floor and discount matrix set the limits once; the system enforces them. Publishing prices and availability only through the portal means everyone works from the same live data. | H12: Strengthens control: under-floor quotes blocked; discounts above the matrix need DOA approval; every price change logged. | I12: =VLOOKUP(A12,'Re-engineering Map'!$A$5:$O$27,14,FALSE())&" → "&VLOOKUP(A12,'Re-engineering Map'!$A$5:$O$27,15,FALSE()) -> Average discount vs list; % of sales with exception discounts → Exception discounts < 5% of sales | J12: 1. [Manual] Sales admin maintains price list per project 2. [Manual] Price list sent to brokers by email 3. [Manual] Broker requests a special discount 4. [Wait] Discount approved case by case 5. [Manual] Availability confirmed by phone | K12: 1. [New] ManCom approves price floors, discount matrix and escalation schedule 2. [Auto] Prices and availability published live on the broker portal 3. [Rule] Discounts within the matrix applied at quotation 4. [Rule] Discounts beyond the matrix routed to DOA approver 5. [Rule] Quotes below the floor blocked 6. [Auto] Scheduled price escalations applied to unsold lots | L12: Emailed price lists and phone checks removed. Case-by-case approvals replaced by a matrix. Floor enforced by the system. | M12: ManCom: sets pricing policy. Sales admin: maintains data, not email lists. Brokers: self-serve prices and availability. Approvers: see only exceptions. | N12: =LEN(J12)-LEN(SUBSTITUTE(J12,CHAR(10),""))+1 -> 5 | O12: =LEN(K12)-LEN(SUBSTITUTE(K12,CHAR(10),""))+1 -> 6 | P12: =(LEN(J12)-LEN(SUBSTITUTE(J12,"[Manual]","")))/8+(LEN(J12)-LEN(SUBSTITUTE(J12,"[Paper]","")))/7+(LEN(J12)-LEN(SUBSTITUTE(J12,"[Rekey]","")))/7+(LEN(J12)-LEN(SUBSTITUTE(J12,"[Wait]","")))/6 -> 5 | Q12: =(LEN(K12)-LEN(SUBSTITUTE(K12,"[Auto]","")))/6+(LEN(K12)-LEN(SUBSTITUTE(K12,"[Rule]","")))/6 -> 5 | R12: =(LEN(K12)-LEN(SUBSTITUTE(K12,"[Earlier]","")))/9+(LEN(K12)-LEN(SUBSTITUTE(K12,"[Parallel]","")))/10 -> 0
A13: RE-09 | B13: =VLOOKUP(A13,'Re-engineering Map'!$A$5:$O$27,2,FALSE()) -> Digital deal jacket from reservation to CTS | C13: =VLOOKUP(A13,'Re-engineering Map'!$A$5:$O$27,3,FALSE()) -> 09 | D13: =VLOOKUP(A13,'Re-engineering Map'!$A$5:$O$27,4,FALSE()) -> Reservation, then document collection, credit check, CTS drafting and notarization in sequence, mostly on paper. | E13: =VLOOKUP(A13,'Re-engineering Map'!$A$5:$O$27,6,FALSE()) -> Buyer uploads KYC and financing documents at reservation (portal with OCR). Completeness checklist per financing scheme. CTS generated from the confirmed sales order with no retyping. Weekly notarization batches. SLA dashboard from reservation to notarized CTS. | F13: Reservation, documentation, credit check and contract drafting happen one after another on paper. Buyers are asked for documents more than once, and CTS details are retyped, so errors and delays push back the start of collections. | G13: Collecting documents once at reservation, with a checklist per financing scheme, removes repeat requests. Generating the CTS from the confirmed sales order removes retyping. An SLA dashboard makes delays visible. | H13: Strengthens compliance: Data Privacy Act consent captured at upload; access restricted by role; CTS still notarized; post-generation changes need approval. | I13: =VLOOKUP(A13,'Re-engineering Map'!$A$5:$O$27,14,FALSE())&" → "&VLOOKUP(A13,'Re-engineering Map'!$A$5:$O$27,15,FALSE()) -> Days from reservation to notarized CTS; % of documents complete at reservation → ≤ 30 days; ≥ 80% | J13: 1. [Paper] Buyer signs reservation form and pays reservation fee 2. [Wait] Sales admin later requests documents 3. [Manual] Buyer submits documents in several rounds 4. [Manual] Credit check performed 5. [Rekey] CTS typed from the reservation and computation 6. [Manual] CTS signed and sent for notarization individually | K13: 1. [Same] Buyer reserves and pays reservation fee 2. [Earlier] Buyer uploads KYC and financing documents at reservation (OCR) 3. [Auto] Completeness checked against the scheme's checklist 4. [Same] Credit check performed 5. [Auto] CTS generated from the confirmed sales order 6. [New] Weekly notarization batches 7. [Auto] SLA dashboard tracks reservation-to-CTS aging | L13: Document collection moved to reservation. CTS retyping removed. Notarization batched. SLA tracking added. | M13: Buyers: submit documents once. Sales admin: checks completeness instead of chasing. Contracts: reviews generated CTSs. Management: monitors aging. | N13: =LEN(J13)-LEN(SUBSTITUTE(J13,CHAR(10),""))+1 -> 6 | O13: =LEN(K13)-LEN(SUBSTITUTE(K13,CHAR(10),""))+1 -> 7 | P13: =(LEN(J13)-LEN(SUBSTITUTE(J13,"[Manual]","")))/8+(LEN(J13)-LEN(SUBSTITUTE(J13,"[Paper]","")))/7+(LEN(J13)-LEN(SUBSTITUTE(J13,"[Rekey]","")))/7+(LEN(J13)-LEN(SUBSTITUTE(J13,"[Wait]","")))/6 -> 6 | Q13: =(LEN(K13)-LEN(SUBSTITUTE(K13,"[Auto]","")))/6+(LEN(K13)-LEN(SUBSTITUTE(K13,"[Rule]","")))/6 -> 3 | R13: =(LEN(K13)-LEN(SUBSTITUTE(K13,"[Earlier]","")))/9+(LEN(K13)-LEN(SUBSTITUTE(K13,"[Parallel]","")))/10 -> 1
A14: RE-10 | B14: =VLOOKUP(A14,'Re-engineering Map'!$A$5:$O$27,2,FALSE()) -> Electronic collections with automatic bank matching | C14: =VLOOKUP(A14,'Re-engineering Map'!$A$5:$O$27,3,FALSE()) -> 11 | D14: =VLOOKUP(A14,'Re-engineering Map'!$A$5:$O$27,4,FALSE()) -> Buyers pay at the cashier or by check/PDC. Cashier issues receipts. Posting and bank matching are manual. | E14: =VLOOKUP(A14,'Re-engineering Map'!$A$5:$O$27,6,FALSE()) -> Move buyers to electronic payment using per-buyer bank references (InstaPay, PESONet, bank over-the-counter). Daily bank file (CSV/MT940) auto-matched to the buyer ledger. Invoice issued on posting. Cashier handles exceptions only. No PDCs for new buyers. | F14: Most payments arrive at the cashier or as checks, so posting depends on manual matching and statements of account lag reality. PDCs create handling risk and bounced-check follow-up. | G14: Giving each buyer a unique bank reference lets the daily bank file be matched to the right ledger automatically. The cashier handles only exceptions, and SOAs are current the same day. | H14: Maintains segregation (receipting, posting, reconciliation by different people), adds daily reconciliation, and issues BIR-registered invoices on posting in line with EOPT. | I14: =VLOOKUP(A14,'Re-engineering Map'!$A$5:$O$27,14,FALSE())&" → "&VLOOKUP(A14,'Re-engineering Map'!$A$5:$O$27,15,FALSE()) -> % of collections received electronically; posting lag → ≥ 70% within 12 months; ≤ 1 working day | J14: 1. [Manual] Buyer pays at cashier or issues check / PDC 2. [Paper] Cashier issues receipt 3. [Manual] PDCs stored and deposited on due dates 4. [Manual] Deposits matched to buyers by hand 5. [Wait] Posting lag; SOA outdated 6. [Manual] Bounced checks followed up | K14: 1. [New] Buyer assigned a unique bank payment reference 2. [Same] Buyer pays by InstaPay, PESONet or bank over-the-counter 3. [Auto] Daily bank file (CSV/MT940) imported and matched to buyer ledger 4. [Auto] Invoice issued on posting; SOA updated same day 5. [Rule] Unmatched items routed to cashier as exceptions 6. [Rule] Daily bank reconciliation signed off | L14: Manual matching and PDC handling removed for new buyers. Posting automated. Cashier role narrowed to exceptions. | M14: Treasury: sets up bank references. Cashier: handles exceptions. Accounting: reviews reconciliation. Buyers: pay without visiting. | N14: =LEN(J14)-LEN(SUBSTITUTE(J14,CHAR(10),""))+1 -> 6 | O14: =LEN(K14)-LEN(SUBSTITUTE(K14,CHAR(10),""))+1 -> 6 | P14: =(LEN(J14)-LEN(SUBSTITUTE(J14,"[Manual]","")))/8+(LEN(J14)-LEN(SUBSTITUTE(J14,"[Paper]","")))/7+(LEN(J14)-LEN(SUBSTITUTE(J14,"[Rekey]","")))/7+(LEN(J14)-LEN(SUBSTITUTE(J14,"[Wait]","")))/6 -> 6 | Q14: =(LEN(K14)-LEN(SUBSTITUTE(K14,"[Auto]","")))/6+(LEN(K14)-LEN(SUBSTITUTE(K14,"[Rule]","")))/6 -> 4 | R14: =(LEN(K14)-LEN(SUBSTITUTE(K14,"[Earlier]","")))/9+(LEN(K14)-LEN(SUBSTITUTE(K14,"[Parallel]","")))/10 -> 0
